Workbook

Sheet GACS Securitizations
A1: Event_ID | B1: Bank | C1: Ticker | D1: SPV_Name | E1: Servicer | F1: GACS_Issuing_Date | G1: Date | H1: GBV_EUR_bn | I1: Pct_Secured | J1: Senior_PctGBV | K1: Mezz_PctGBV | L1: Junior_PctGBV | M1: Senior_Yield | N1: Mezz_Yield | O1: Buyer | P1: GACS | Q1: Deal_Type | R1: Capital_Raise_Simultaneous | S1: Bank_NPL_Ratio | T1: Bank_CET1 | U1: Crisis_Period | V1: PwC_Source | W1: Notes
A2: GACS-001 | B2: UniCredit | C2: UCG | D2: FINO 1 Securitisation S.r.l. | E2: doValue | F2: Nov-17 | G2: 43081 | H2: 5.4 | I2: 52.0% | J2: 12.1% | K2: 1.3% | L2: 0.9% | M2: 5.1% | N2: 8.7% | O2: Fortress/PIMCO | P2: Yes | Q2: Bad Loans | U2: Yes | V2: PwC Dec 2023 pp.20-21
A3: GACS-002 | B3: MPS | C3: BMPS | D3: Siena NPL 2018 S.r.l. | E3: Cerved/Prelios/doValue/CF | F3: Jan-18 | G3: 43230 | H3: 24.1 | I3: 41.6% | J3: 12.1% | K3: 3.5% | L3: 2.3% | M3: 5.1% | N3: 11.6% | O3: Quaestio/Atlante II | P3: Yes | Q3: Bad Loans | U3: No | V3: PwC Dec 2023 pp.20-21
A4: GACS-003 | B4: BPER | C4: BPE | D4: 4Mori Sardegna S.r.l. | E4: Prelios | F4: Jun-18 | G4: 43273 | H4: 1 | I4: 53.0% | J4: 22.2% | K4: 1.2% | L4: 0.8% | M4: 1.4% | N4: 11.9% | O4: n.a. | P4: Yes | Q4: Bad Loans | U4: No | V4: PwC Dec 2023 pp.20-21
A5: GACS-004 | B5: Banco BPM | C5: BAMI | D5: Red Sea SPV S.r.l. | E5: Prelios | F5: Jul-18 | G5: 43251 | H5: 5.1 | I5: 76.6% | J5: 32.5% | K5: 3.0% | L5: 1.0% | M5: 4.5% | N5: 9.9% | O5: n.a. | P5: Yes | Q5: Bad Loans | U5: No | V5: PwC Dec 2023 pp.20-21
A6: GACS-005 | B6: BPER | C6: BPE | D6: Aqui SPV S.r.l. | E6: Prelios | F6: Nov-18 | G6: 43412 | H6: 2.1 | I6: 59.5% | J6: 26.2% | K6: 3.0% | L6: 0.5% | M6: 2.0% | N6: 10.9% | O6: n.a. | P6: Yes | Q6: Bad Loans | U6: No | V6: PwC Dec 2023 pp.20-21
A7: GACS-006 | B7: Banco BPM | C7: BAMI | D7: Leviticus SPV S.r.l. | E7: Credito Fondiario | F7: Feb-19 | G7: 43444 | H7: 7.4 | I7: 66.9% | J7: 19.5% | K7: 3.0% | L7: 3.4% | M7: 2.1% | N7: 11.9% | O7: n.a. | P7: Yes | Q7: Bad Loans | U7: No | V7: PwC Dec 2023 pp.20-21
A8: GACS-007 | B8: UniCredit | C8: UCG | D8: Prisma SPV S.r.l. | E8: doValue | F8: Oct-19 | G8: 43756 | H8: 6.1 | I8: 64.0% | J8: 20.0% | K8: 1.3% | L8: 0.5% | M8: 5.4% | N8: 12.9% | O8: n.a. | P8: Yes | Q8: Bad Loans | U8: No | V8: PwC Dec 2023 pp.20-21
A9: GACS-008 | B9: BPER | C9: BPE | D9: Spring SPV S.r.l. | E9: Prelios | F9: Jun-20 | G9: 44000 | H9: 1.4 | I9: 52.5% | J9: 23.2% | K9: 1.5% | L9: 0.2% | M9: 4.4% | N9: 13.4% | O9: n.a. | P9: Yes | Q9: Bad Loans | U9: No | V9: PwC Dec 2023 pp.20-21
A10: GACS-009 | B10: Banca Popolare di Sondrio | C10: BPSO | D10: Diana SPV S.r.l. | E10: Prelios | F10: Jun-20 | G10: 43999 | H10: 1 | I10: 64.7% | J10: 23.5% | K10: 3.5% | L10: 0.4% | M10: 4.4% | N10: 12.9% | O10: n.a. | P10: Yes | Q10: Bad Loans | U10: No | V10: PwC Dec 2023 pp.20-21
A11: GACS-010 | B11: UniCredit | C11: UCG | D11: Relais SPV S.r.l. | E11: doValue | F11: Dec-20 | G11: 44179 | H11: 1.6 | I11: 86.5% | J11: 29.4% | K11: 5.7% | L11: 0.6% | M11: 5.4% | N11: 13.4% | O11: n.a. | P11: Yes | Q11: Bad Loans | U11: No | V11: PwC Dec 2023 pp.20-21
A12: GACS-011 | B12: Intesa Sanpaolo | C12: ISP | D12: Yoda SPV S.r.l. | E12: Intrum | F12: Dec-20 | G12: 44183 | H12: 6 | I12: 41.2% | J12: 16.7% | K12: 3.5% | L12: 0.3% | M12: 4.1% | N12: 13.1% | O12: n.a. | P12: Yes | Q12: Bad Loans | U12: No | V12: PwC Dec 2023 pp.20-21
A13: GACS-012 | B13: BPER | C13: BPE | D13: Summer SPV S.r.l. | E13: Fire | F13: Dec-20 | G13: 44195 | H13: 0.3 | I13: 44.4% | J13: 26.5% | K13: 3.1% | L13: 0.3% | M13: 4.4% | N13: 15.9% | O13: Institutional inv. | P13: Yes | Q13: Bad Loans | U13: No | V13: PwC Dec 2023 pp.20-21
... A19: GACS-018 | B19: UniCredit | C19: UCG | D19: Itaca SPV S.r.l. | E19: doValue | F19: Jun-22 | G19: 44727 | H19: 1.1 | I19: 29.0% | J19: 11.1% | K19: 2.1% | L19: 0.5% | M19: 4.9% | N19: 13.4% | O19: CRC | P19: Yes | Q19: Bad Loans | U19: No | V19: PwC Dec 2023 pp.20-21
B23: Company | C23: Ticker | D23: Count
B24: {=_xlfn.UNIQUE(B2:B19)} -> UniCredit | C24: =VLOOKUP(B24,$B$2:$C$19,2, FALSE) -> UCG | D24: =COUNTIF($C$2:$C$19,C24) -> 5
B25: MPS | C25: =VLOOKUP(B25,$B$2:$C$19,2, FALSE) -> BMPS | D25: =COUNTIF($C$2:$C$19,C25) -> 1
B26: BPER | C26: =VLOOKUP(B26,$B$2:$C$19,2, FALSE) -> BPE | D26: =COUNTIF($C$2:$C$19,C26) -> 4
B27: Banco BPM | C27: =VLOOKUP(B27,$B$2:$C$19,2, FALSE) -> BAMI | D27: =COUNTIF($C$2:$C$19,C27) -> 3
B28: Banca Popolare di Sondrio | C28: =VLOOKUP(B28,$B$2:$C$19,2, FALSE) -> BPSO | D28: =COUNTIF($C$2:$C$19,C28) -> 2
B29: Intesa Sanpaolo | C29: =VLOOKUP(B29,$B$2:$C$19,2, FALSE) -> ISP | D29: =COUNTIF($C$2:$C$19,C29) -> 2
B30: Intesa Sanpaolo/BPER | C30: =VLOOKUP(B30,$B$2:$C$19,2, FALSE) -> ISP/BPE | D30: =COUNTIF($C$2:$C$19,C30) -> 1
B32: UCG | D32: Price on event day | E32: Pfm 1 day | F32: Pfm next three days | G32: Pfm 1 week | H32: Pfm 1 month
C33: {=_xlfn._xlws.FILTER($G$2:$G$19,$C$2:$C$19=B32)} -> 43081 | D33: =SUM(_xldudf_WISEPRICE($B$32 & ".MI", "Close",, TEXT($C33, "yyyy-mm-dd"), TEXT($C33, "yyyy-mm-dd"))) -> 17.41 | E33: =(SUM(_xldudf_WISEPRICE($B$32 & ".MI", "Close",, TEXT(WORKDAY($C33, 1), "yyyy-mm-dd"), TEXT(WORKDAY($C33, 1), "yyyy-mm-dd"))) / $D33) - 1 -> -0.046524986 | F33: =(SUM(_xldudf_WISEPRICE($B$32 & ".MI", "Close",, TEXT(WORKDAY($C33, 3), "yyyy-mm-dd"), TEXT(WORKDAY($C33, 3), "yyyy-mm-dd"))) / $D33) - 1 -> -0.0723722 | G33: =(SUM(_xldudf_WISEPRICE($B$32 & ".MI", "Close",, TEXT(WORKDAY($C33, 5), "yyyy-mm-dd"), TEXT(WORKDAY($C33, 5), "yyyy-mm-dd"))) / $D33) - 1 -> -0.050545663 | H33: =(SUM(_xldudf_WISEPRICE($B$32 & ".MI", "Close",, TEXT(WORKDAY(EDATE($C33, 1)-1, 1), "yyyy-mm-dd"), TEXT(WORKDAY(EDATE($C33, 1)-1, 1), "yyyy-mm-dd"))) / $D33) - 1 -> 0.0034462952
C34: 43756 | D34: =SUM(_xldudf_WISEPRICE("UCG.MI","Close",,C34,C34)) -> 11.5 | E34: =(SUM(_xldudf_WISEPRICE($B$32 & ".MI", "Close",, TEXT(WORKDAY($C34, 1), "yyyy-mm-dd"), TEXT(WORKDAY($C34, 1), "yyyy-mm-dd"))) / $D34) - 1 -> 0.020869565 | F34: =(SUM(_xldudf_WISEPRICE($B$32 & ".MI", "Close",, TEXT(WORKDAY($C34, 3), "yyyy-mm-dd"), TEXT(WORKDAY($C34, 3), "yyyy-mm-dd"))) / $D34) - 1 -> 0.013913043 | G34: =(SUM(_xldudf_WISEPRICE($B$32 & ".MI", "Close",, TEXT(WORKDAY($C34, 5), "yyyy-mm-dd"), TEXT(WORKDAY($C34, 5), "yyyy-mm-dd"))) / $D34) - 1 -> 0.0026086957 | H34: =(SUM(_xldudf_WISEPRICE($B$32 & ".MI", "Close",, TEXT(WORKDAY(EDATE($C34, 1)-1, 1), "yyyy-mm-dd"), TEXT(WORKDAY(EDATE($C34, 1)-1, 1), "yyyy-mm-dd"))) / $D34) - 1 -> 0.073043478
C35: 44179 | D35: =SUM(_xldudf_WISEPRICE("UCG.MI","Close",,C35,C35)) -> 7.69 | E35: =(SUM(_xldudf_WISEPRICE($B$32 & ".MI", "Close",, TEXT(WORKDAY($C35, 1), "yyyy-mm-dd"), TEXT(WORKDAY($C35, 1), "yyyy-mm-dd"))) / $D35) - 1 -> 0.026007802 | F35: =(SUM(_xldudf_WISEPRICE($B$32 & ".MI", "Close",, TEXT(WORKDAY($C35, 3), "yyyy-mm-dd"), TEXT(WORKDAY($C35, 3), "yyyy-mm-dd"))) / $D35) - 1 -> 0.013003901 | G35: =(SUM(_xldudf_WISEPRICE($B$32 & ".MI", "Close",, TEXT(WORKDAY($C35, 5), "yyyy-mm-dd"), TEXT(WORKDAY($C35, 5), "yyyy-mm-dd"))) / $D35) - 1 -> -0.035110533 | H35: =(SUM(_xldudf_WISEPRICE($B$32 & ".MI", "Close",, TEXT(WORKDAY(EDATE($C35, 1)-1, 1), "yyyy-mm-dd"), TEXT(WORKDAY(EDATE($C35, 1)-1, 1), "yyyy-mm-dd"))) / $D35) - 1 -> 0.019505852
C36: 44525 | D36: =SUM(_xldudf_WISEPRICE("UCG.MI","Close",,C36,C36)) -> 11.27 | E36: =(SUM(_xldudf_WISEPRICE($B$32 & ".MI", "Close",, TEXT(WORKDAY($C36, 1), "yyyy-mm-dd"), TEXT(WORKDAY($C36, 1), "yyyy-mm-dd"))) / $D36) - 1 -> -0.069210293 | F36: =(SUM(_xldudf_WISEPRICE($B$32 & ".MI", "Close",, TEXT(WORKDAY($C36, 3), "yyyy-mm-dd"), TEXT(WORKDAY($C36, 3), "yyyy-mm-dd"))) / $D36) - 1 -> -0.051464064 | G36: =(SUM(_xldudf_WISEPRICE($B$32 & ".MI", "Close",, TEXT(WORKDAY($C36, 5), "yyyy-mm-dd"), TEXT(WORKDAY($C36, 5), "yyyy-mm-dd"))) / $D36) - 1 -> -0.023070098 | H36: =(SUM(_xldudf_WISEPRICE($B$32 & ".MI", "Close",, TEXT(WORKDAY(EDATE($C36, 1)-1, 1), "yyyy-mm-dd"), TEXT(WORKDAY(EDATE($C36, 1)-1, 1), "yyyy-mm-dd"))) / $D36) - 1 -> 0.20053239
C37: 44727 | D37: =SUM(_xldudf_WISEPRICE("UCG.MI","Close",,C37,C37)) -> 10.08 | E37: =(SUM(_xldudf_WISEPRICE($B$32 & ".MI", "Close",, TEXT(WORKDAY($C37, 1), "yyyy-mm-dd"), TEXT(WORKDAY($C37, 1), "yyyy-mm-dd"))) / $D37) - 1 -> -0.032738095 | F37: =(SUM(_xldudf_WISEPRICE($B$32 & ".MI", "Close",, TEXT(WORKDAY($C37, 3), "yyyy-mm-dd"), TEXT(WORKDAY($C37, 3), "yyyy-mm-dd"))) / $D37) - 1 -> 0.015873016 | G37: =(SUM(_xldudf_WISEPRICE($B$32 & ".MI", "Close",, TEXT(WORKDAY($C37, 5), "yyyy-mm-dd"), TEXT(WORKDAY($C37, 5), "yyyy-mm-dd"))) / $D37) - 1 -> 0.013888889 | H37: =(SUM(_xldudf_WISEPRICE($B$32 & ".MI", "Close",, TEXT(WORKDAY(EDATE($C37, 1)-1, 1), "yyyy-mm-dd"), TEXT(WORKDAY(EDATE($C37, 1)-1, 1), "yyyy-mm-dd"))) / $D37) - 1 -> -0.14980159
C38: Average Performance | D38: =_xlfn.AGGREGATE(1,6,D33:D37) -> 11.59 | E38: =_xlfn.AGGREGATE(1,6,E33:E37) -> -0.020319201 | F38: =_xlfn.AGGREGATE(1,6,F33:F37) -> -0.016209261 | G38: =_xlfn.AGGREGATE(1,6,G33:G37) -> -0.018445742 | H38: =_xlfn.AGGREGATE(1,6,H33:H37) -> 0.029345285
B39: BMPS | D39: Price on event day | E39: Pfm 1 day | F39: Pfm next three days | G39: Pfm 1 week | H39: Pfm 1 month
C40: {=_xlfn._xlws.FILTER($G$2:$G$19,$C$2:$C$19=B39)} -> 43230 | D40: =SUM(_xldudf_WISEPRICE($B$39 & ".MI", "Close",, TEXT($C40, "yyyy-mm-dd"), TEXT($C40, "yyyy-mm-dd"))) -> 272 | E40: =(SUM(_xldudf_WISEPRICE($B$39 & ".MI", "Close",, TEXT(WORKDAY($C40, 1), "yyyy-mm-dd"), TEXT(WORKDAY($C40, 1), "yyyy-mm-dd"))) / $D40) - 1 -> 0.17647059 | F40: =(SUM(_xldudf_WISEPRICE($B$39 & ".MI", "Close",, TEXT(WORKDAY($C40, 3), "yyyy-mm-dd"), TEXT(WORKDAY($C40, 3), "yyyy-mm-dd"))) / $D40) - 1 -> 0.1875 | G40: =(SUM(_xldudf_WISEPRICE($B$39 & ".MI", "Close",, TEXT(WORKDAY($C40, 5), "yyyy-mm-dd"), TEXT(WORKDAY($C40, 5), "yyyy-mm-dd"))) / $D40) - 1 -> 0.074632309 | H40: =(SUM(_xldudf_WISEPRICE($B$39 & ".MI", "Close",, TEXT(WORKDAY(EDATE($C40, 1)-1, 1), "yyyy-mm-dd"), TEXT(WORKDAY(EDATE($C40, 1)-1, 1), "yyyy-mm-dd"))) / $D40) - 1 -> 0.022058824
C41: Average Performance | D41: =_xlfn.AGGREGATE(1,6,D40:D40) -> 272 | E41: =_xlfn.AGGREGATE(1,6,E40:E40) -> 0.17647059 | F41: =_xlfn.AGGREGATE(1,6,F40:F40) -> 0.1875 | G41: =_xlfn.AGGREGATE(1,6,G40:G40) -> 0.074632309 | H41: =_xlfn.AGGREGATE(1,6,H40:H40) -> 0.022058824
B42: BPE | D42: Price on event day | E42: Pfm 1 day | F42: Pfm next three days | G42: Pfm 1 week | H42: Pfm 1 month
C43: {=_xlfn._xlws.FILTER($G$2:$G$19,$C$2:$C$19=B42)} -> 43273 | D43: =SUM(_xldudf_WISEPRICE($B$42 & ".MI", "Close",, TEXT($C43, "yyyy-mm-dd"), TEXT($C43, "yyyy-mm-dd"))) -> 3.24 | E43: =(SUM(_xldudf_WISEPRICE($B$42 & ".MI", "Close",, TEXT(WORKDAY($C43, 1), "yyyy-mm-dd"), TEXT(WORKDAY($C43, 1), "yyyy-mm-dd"))) / $D43) - 1 -> -0.021604938 | F43: =(SUM(_xldudf_WISEPRICE($B$42 & ".MI", "Close",, TEXT(WORKDAY($C43, 3), "yyyy-mm-dd"), TEXT(WORKDAY($C43, 3), "yyyy-mm-dd"))) / $D43) - 1 -> -0.030864198 | G43: =(SUM(_xldudf_WISEPRICE($B$42 & ".MI", "Close",, TEXT(WORKDAY($C43, 5), "yyyy-mm-dd"), TEXT(WORKDAY($C43, 5), "yyyy-mm-dd"))) / $D43) - 1 -> -0.015432099 | H43: =(SUM(_xldudf_WISEPRICE($B$42 & ".MI", "Close",, TEXT(WORKDAY(EDATE($C43, 1)-1, 1), "yyyy-mm-dd"), TEXT(WORKDAY(EDATE($C43, 1)-1, 1), "yyyy-mm-dd"))) / $D43) - 1 -> -0.052469136
C44: 43412 | D44: =SUM(_xldudf_WISEPRICE($B$42 & ".MI", "Close",, TEXT($C44, "yyyy-mm-dd"), TEXT($C44, "yyyy-mm-dd"))) -> 2.34 | E44: =(SUM(_xldudf_WISEPRICE($B$42 & ".MI", "Close",, TEXT(WORKDAY($C44, 1), "yyyy-mm-dd"), TEXT(WORKDAY($C44, 1), "yyyy-mm-dd"))) / $D44) - 1 -> 0.0085470085 | F44: =(SUM(_xldudf_WISEPRICE($B$42 & ".MI", "Close",, TEXT(WORKDAY($C44, 3), "yyyy-mm-dd"), TEXT(WORKDAY($C44, 3), "yyyy-mm-dd"))) / $D44) - 1 -> 0.012820513 | G44: =(SUM(_xldudf_WISEPRICE($B$42 & ".MI", "Close",, TEXT(WORKDAY($C44, 5), "yyyy-mm-dd"), TEXT(WORKDAY($C44, 5), "yyyy-mm-dd"))) / $D44) - 1 -> -0.012820513 | H44: =(SUM(_xldudf_WISEPRICE($B$42 & ".MI", "Close",, TEXT(WORKDAY(EDATE($C44, 1)-1, 1), "yyyy-mm-dd"), TEXT(WORKDAY(EDATE($C44, 1)-1, 1), "yyyy-mm-dd"))) / $D44) - 1 -> 0.021367521
C45: 44000 | D45: =SUM(_xldudf_WISEPRICE($B$42 & ".MI", "Close",, TEXT($C45, "yyyy-mm-dd"), TEXT($C45, "yyyy-mm-dd"))) -> 1.58 | E45: =(SUM(_xldudf_WISEPRICE($B$42 & ".MI", "Close",, TEXT(WORKDAY($C45, 1), "yyyy-mm-dd"), TEXT(WORKDAY($C45, 1), "yyyy-mm-dd"))) / $D45) - 1 -> 0.012658228 | F45: =(SUM(_xldudf_WISEPRICE($B$42 & ".MI", "Close",, TEXT(WORKDAY($C45, 3), "yyyy-mm-dd"), TEXT(WORKDAY($C45, 3), "yyyy-mm-dd"))) / $D45) - 1 -> -0.0063291139 | G45: =(SUM(_xldudf_WISEPRICE($B$42 & ".MI", "Close",, TEXT(WORKDAY($C45, 5), "yyyy-mm-dd"), TEXT(WORKDAY($C45, 5), "yyyy-mm-dd"))) / $D45) - 1 -> -0.044303797 | H45: =(SUM(_xldudf_WISEPRICE($B$42 & ".MI", "Close",, TEXT(WORKDAY(EDATE($C45, 1)-1, 1), "yyyy-mm-dd"), TEXT(WORKDAY(EDATE($C45, 1)-1, 1), "yyyy-mm-dd"))) / $D45) - 1 -> 0.063291139
C46: 44195 | D46: =SUM(_xldudf_WISEPRICE($B$42 & ".MI", "Close",, TEXT($C46, "yyyy-mm-dd"), TEXT($C46, "yyyy-mm-dd"))) -> 1.49 | E46: / | F46: =(SUM(_xldudf_WISEPRICE($B$42 & ".MI", "Close",, TEXT(WORKDAY($C46, 3), "yyyy-mm-dd"), TEXT(WORKDAY($C46, 3), "yyyy-mm-dd"))) / $D46) - 1 -> -0.020134228 | G46: =(SUM(_xldudf_WISEPRICE($B$42 & ".MI", "Close",, TEXT(WORKDAY($C46, 5), "yyyy-mm-dd"), TEXT(WORKDAY($C46, 5), "yyyy-mm-dd"))) / $D46) - 1 -> 0.040268456 | H46: =(SUM(_xldudf_WISEPRICE($B$42 & ".MI", "Close",, TEXT(WORKDAY(EDATE($C46, 1)-1, 1), "yyyy-mm-dd"), TEXT(WORKDAY(EDATE($C46, 1)-1, 1), "yyyy-mm-dd"))) / $D46) - 1 -> 0.026845638
C47: Average Performance | D47: =_xlfn.AGGREGATE(1,6,D43:D46) -> 2.1625 | E47: =_xlfn.AGGREGATE(1,6,E43:E46) -> -0.00013323396 | F47: =_xlfn.AGGREGATE(1,6,F43:F46) -> -0.011126757 | G47: =_xlfn.AGGREGATE(1,6,G43:G46) -> -0.0080719882 | H47: =_xlfn.AGGREGATE(1,6,H43:H46) -> 0.014758791
B48: BAMI
D49: Price on event day | E49: Pfm 1 day | F49: Pfm next three days | G49: Pfm 1 week | H49: Pfm 1 month
...

Sheet Non-GACS Deals
A1: Event_ID | B1: Bank | C1: Ticker | D1: Date_Quarter | E1: Date | F1: GBV_EUR_m | G1: NPE_Category | H1: Asset_Class | I1: Buyer | J1: Project_Name | K1: GACS | L1: Capital_Raise_Simultaneous | M1: Bank_NPL_Ratio | N1: Bank_CET1 | O1: Crisis_Period | P1: PwC_Source | Q1: Notes
A2: NG-001 | B2: UniCredit | C2: UCG | D2: 2015 Q1 | E2: 42046 | F2: 2400 | G2: Bad Loans | H2: Mixed Sec/Unsec | I2: Fortress & Prelios | J2: Platform sale + UCCMB | K2: No | O2: Yes | P2: PwC Jun 2016 p.23
A3: NG-002 | B3: UniCredit | C3: UCG | D3: 2015 Q2 | E3: 42185 | F3: 625 | G3: Bad Loans | H3: Unsecured | I3: PRA | K3: No | O3: Yes | P3: PwC Jun 2016 p.23
A4: NG-003 | B4: UniCredit | C4: UCG | D4: 2015 Q2 | E4: 42186 | F4: 205 | G4: Bad Loans | H4: Leasing | I4: Cerberus | K4: No | O4: Yes | P4: PwC Jun 2016 p.23
A5: NG-004 | B5: UniCredit | C5: UCG | D5: 2015 Q3 | E5: 42275 | F5: 1200 | G5: Bad Loans | H5: Mainly Unsecured | I5: Anacap | K5: No | O5: Yes | P5: PwC Jun 2016 p.23
A6: NG-005 | B6: UniCredit | C6: UCG | D6: 2015 Q4 | E6: 42355 | F6: 250 | G6: Bad Loans | H6: Mixed Sec/Unsec | I6: Cerberus | K6: No | O6: Yes | P6: PwC Jun 2016 p.23
A7: NG-006 | B7: MPS | C7: BMPS | D7: 2015 Q2 | E7: 42178 | F7: 1300 | G7: Bad Loans | H7: Consumer | I7: Banca IFIS/Cerberus | J7: Consum.it portfolio | K7: No | O7: Yes | P7: PwC Jun 2016 p.23
A8: NG-007 | B8: MPS | C8: BMPS | D8: 2015 Q4 | E8: 42366 | F8: 1700 | G8: Bad Loans | H8: Unsecured | I8: Deutsche Bank | K8: No | O8: Yes | P8: PwC Jun 2016 p.23
A9: NG-008 | B9: UniCredit | C9: UCG | D9: 2017 Q1 | E9: 42717 | F9: 17700 | G9: Bad Loans | H9: Mixed Sec/Unsec | I9: Fortress/PIMCO | J9: Project Fino (total incl. GACS) | K9: No | O9: Yes | P9: PwC Jul 2017 p.21
A10: NG-009 | B10: Intesa Sanpaolo | C10: ISP | D10: 2017 Q2 | E10: 42859 | F10: 2500 | G10: Bad Loans | H10: Mixed | I10: Christofferson Robb/Bayview | J10: Project Beyond the Clouds | K10: No | O10: Yes | P10: PwC Jul 2017 p.21
A11: NG-010 | B11: Banco BPM | C11: BAMI | D11: 2017 Q2 | E11: 42908 | F11: 750 | G11: Bad Loans | H11: n.a. | I11: Algebris Investments | J11: Project Rainbow | K11: No | O11: Yes | P11: PwC Jul 2017 p.21
A12: NG-011 | B12: Intesa Sanpaolo | C12: ISP | D12: 2018 Q2 | E12: 43206 | F12: 10800 | G12: Bad Loans | H12: Mainly Secured | I12: Intrum | J12: ISP-Intrum deal | K12: No | O12: No | P12: PwC Dec 2019 p.52
A13: NG-012 | B13: Banco BPM | C13: BAMI | D13: 2018 Q2 | E13: 43270 | F13: 5100 | G13: Bad Loans | H13: Mainly Secured | I13: CRC | K13: No | O13: No | P13: PwC Dec 2019 p.52
A14: NG-013 | B14: MPS | C14: BMPS | D14: 2018 Q3 | E14: 43497 | F14: 300 | G14: UtP | H14: Secured | I14: Confidential | K14: No | O14: No | P14: PwC Dec 2019 p.52
A15: NG-014 | B15: MPS | C15: BMPS | D15: 2018 Q3 | E15: 43313 | F15: 135 | G15: NPE | H15: Secured | I15: SC Lowy | K15: No | O15: No | P15: PwC Dec 2019 p.52
A16: NG-015 | B16: MPS | C16: BMPS | D16: 2018 Q4 | E16: 43497 | F16: 2200 | G16: Bad Loans | H16: Unsecured | I16: IFIS NPL/CF/Balbec | K16: No | O16: No | P16: PwC Dec 2019 p.51
A17: NG-016 | B17: MPS | C17: BMPS | D17: 2018 Q4 | E17: 43454 | F17: 900 | G17: Bad Loans | H17: Mixed Sec/Unsec | I17: Bain Capital Credit | J17: Project Morgana (leasing) | K17: No | O17: No | P17: PwC Dec 2019 p.51
A18: NG-017 | B18: MPS | C18: BMPS | D18: 2018 Q1 | E18: 43190 | F18: 100 | G18: UtP | H18: Secured | I18: Confidential | K18: No | O18: No | P18: PwC Dec 2019 p.52
A19: NG-018 | B19: MPS | C19: BMPS | D19: 2018 Q2 | E19: 43281 | F19: 500 | G19: UtP | H19: Secured | I19: Confidential | J19: Aggregate single names | K19: No | O19: No | P19: PwC Dec 2019 p.52
A20: NG-019 | B20: BPER | C20: BPE | D20: 2018 Q4 | E20: 43454 | F20: 200 | G20: Bad Loans | H20: Mixed Sec/Unsec | I20: MBCredit Solutions | K20: No | O20: No | P20: PwC Dec 2019 p.51 | X20: Event ID | Y20: Verified Date | Z20: Verified GBV (€m) | AA20: Notes
A21: NG-020 | B21: UniCredit | C21: UCG | D21: 2018 Q4 | E21: 43445 | F21: 642 | G21: Bad Loans | H21: Secured | I21: Fortress | K21: No | O21: No | P21: PwC Dec 2019 p.51 | X21: NG-020 | Y21: 43445 | Z21: 642 | AA21: Correct. Portfolio sold to Fortress.
A22: NG-021 | B22: UniCredit | C22: UCG | D22: 2018 Q4 | E22: 43454 | F22: 449 | G22: Bad Loans | H22: Unsecured | I22: J-Invest & illimity | K22: No | O22: No | P22: PwC Dec 2019 p.51 | X22: NG-021 | Y22: 43454 | Z22: 450 | AA22: Correct (rounded from 449). Sold to J-Invest and illimity.
A23: NG-022 | B23: UniCredit | C23: UCG | D23: 2018 Q4 | E23: 43462 | F23: 170 | G23: Bad Loans | H23: Unsecured | I23: Guber | K23: No | O23: No | P23: PwC Dec 2019 p.51 | X23: NG-022 | Y23: 43462 | Z23: 170 | AA23: Correct. Sold to Guber Banca.
A24: NG-023 | B24: UniCredit | C24: UCG | D24: 2018 Q3 | E24: 43371 | F24: 1090 | G24: NPE | H24: Unsecured | I24: IFIS NPL | K24: No | O24: No | P24: PwC Dec 2019 p.51 | X24: NG-023 | Y24: 43371 | Z24: 1090 | AA24: Correct. Consumer and credit card loans to IFIS.
A25: NG-024 | B25: UniCredit | C25: UCG | D25: 2018 Q3 | E25: 43315 | F25: 537 | G25: NPE | H25: Mixed Sec/Unsec | I25: Banca IFIS | K25: No | O25: No | P25: PwC Dec 2019 p.51 | X25: NG-024 | Y25: 43315 | Z25: 537 | AA25: Adjustment. Official announcement was Aug 3, not Aug 31.
A26: NG-025 | B26: UniCredit | C26: UCG | D26: 2018 Q2 | E26: 43280 | F26: 124 | G26: NPE | H26: Unsecured | I26: MBCredit Solutions | K26: No | O26: No | P26: PwC Dec 2019 p.52 | X26: NG-025 | Y26: 43280 | Z26: 124 | AA26: Correct. Small unsecured portfolio to MBCredit.
A27: NG-026 | B27: UniCredit | C27: UCG | D27: 2019 Q4 | E27: 43818 | F27: 1039 | G27: Bad Loans | H27: Unsecured | I27: Confidential | K27: No | O27: No | P27: PwC Dec 2019 p.50 | X27: NG-026 | Y27: 43818 | Z27: 1039 | AA27: Correct. Major unsecured bad loan disposal.
A28: NG-027 | B28: UniCredit | C28: UCG | D28: 2019 Q3 | E28: 43734 | F28: 1100 | G28: Bad Loans | H28: Unsecured | I28: SPF Investment Mgmt | K28: No | O28: No | P28: PwC Dec 2019 p.50 | X28: NG-027 | Y28: 43734 | Z28: 1100 | AA28: Correct. Sold to SPF Investment Management.
A29: NG-028 | B29: UniCredit | C29: UCG | D29: 2019 Q3 | E29: 43735 | F29: 664 | G29: Bad Loans | H29: Secured | I29: illimity | K29: No | O29: No | P29: PwC Dec 2019 p.50 | X29: NG-028 | Y29: 43735 | Z29: 664 | AA29: Correct. Real estate secured portfolio to illimity.
A30: NG-029 | B30: UniCredit | C30: UCG | D30: 2019 Q3 | E30: 43738 | F30: 375 | G30: Bad Loans | H30: Mainly Unsecured | I30: n.a. | K30: No | O30: No | P30: PwC Dec 2019 p.50 | X30: NG-029 | Y30: 43738 | Z30: 375 | AA30: Correct. Part of the "Sandokan" series of disposals.
A31: NG-030 | B31: UniCredit | C31: UCG | D31: 2019 Q3 | E31: 43812 | F31: 240 | G31: Bad Loans | H31: Unsecured | I31: illimity | K31: No | O31: No | P31: PwC Dec 2019 p.50 | X31: NG-030 | Y31: 43812 | Z31: 240 | AA31: Adjustment. This specific deal with illimity was announced Dec 13.
A32: NG-031 | B32: UniCredit | C32: UCG | D32: 2019 Q3 | E32: 43804 | F32: 210 | G32: Bad Loans | H32: Unsecured | I32: Guber & Barclays | K32: No | O32: No | P32: PwC Dec 2019 p.50 | X32: NG-031 | Y32: 43804 | Z32: 210 | AA32: Correct. Announced during the 2019-2023 Strategic Plan rollout.
A33: NG-032 | B33: Intesa Sanpaolo | C33: ISP | D33: 2019 Q3 | E33: 43733 | F33: 3000 | G33: UtP | H33: Mixed Sec/Unsec | I33: DK / Prelios | J33: Project M | K33: No | O33: No | P33: PwC Dec 2019 p.50
A34: NG-033 | B34: Intesa Sanpaolo | C34: ISP | D34: 2019 Q1 | E34: 43552 | F34: 187 | G34: NPE | H34: Secured | I34: WRM | K34: No | O34: No | P34: PwC Dec 2019 p.50
A35: NG-034 | B35: MPS | C35: BMPS | D35: 2019 Q3 | E35: 43738 | F35: 455 | G35: UtP | H35: Secured | I35: Cerberus | K35: No | O35: No | P35: PwC Dec 2019 p.50
A36: NG-035 | B36: MPS | C36: BMPS | D36: 2019 Q3 | E36: 43677 | F36: 450 | G36: UtP | H36: Mainly Unsecured | I36: illimity | K36: No | O36: No | P36: PwC Dec 2019 p.50
A37: NG-036 | B37: MPS | C37: BMPS | D37: 2019 Q3 | E37: 43677 | F37: 240 | G37: Bad Loans | H37: Mixed Sec/Unsec | I37: illimity | K37: No | O37: No | P37: PwC Dec 2019 p.50
A38: NG-037 | B38: MPS | C38: BMPS | D38: 2019 Q3 | E38: 43690 | F38: 202 | G38: UtP | H38: Mainly Secured | I38: Unknown | K38: No | O38: No | P38: PwC Dec 2019 p.50
A39: NG-038 | B39: MPS | C39: BMPS | D39: 2019 Q3 | E39: 43690 | F39: 137 | G39: Bad Loans | H39: Mixed Sec/Unsec | I39: Unknown | K39: No | O39: No | P39: PwC Dec 2019 p.50
A40: NG-039 | B40: MPS | C40: BMPS | D40: 2019 Q3 | E40: 43614 | F40: 130 | G40: UtP | H40: Secured | I40: BofA Merrill Lynch | K40: No | O40: No | P40: PwC Dec 2019 p.50
...

Sheet Non-GACS Analysis
B1: Company | C1: Ticker | D1: Count
B2: UniCredit | C2: UCG | D2: 27
B3: MPS | C3: BMPS | D3: 19
B4: Intesa Sanpaolo | C4: ISP | D4: 11
B5: Banco BPM | C5: BAMI | D5: 5
B6: BPER | C6: BPE | D6: 6
B8: UCG | D8: Price on event day | E8: Pfm 1 day | F8: Pfm next three days | G8: Pfm 1 week | H8: Pfm 1 month
C9: 42046 | D9: =IF(SUM(_xldudf_WISEPRICE($B$8 & ".MI", "Close",, TEXT(WORKDAY($C9+1,-1), "yyyy-mm-dd"), TEXT(WORKDAY($C9+1,-1), "yyyy-mm-dd")))=0, "/", SUM(_xldudf_WISEPRICE($B$8 & ".MI", "Close",, TEXT(WORKDAY($C9+1,-1), "yyyy-mm-dd"), TEXT(WORKDAY($C9+1,-1), "yyyy-mm-dd")))) -> 26.55 | E9: =IFERROR(IF(SUM(_xldudf_WISEPRICE($B$8 & ".MI", "Close",, TEXT(WORKDAY(WORKDAY($C9+1,-1), 1), "yyyy-mm-dd"), TEXT(WORKDAY(WORKDAY($C9+1,-1), 1), "yyyy-mm-dd")))=0, "/", (SUM(_xldudf_WISEPRICE($B$8 & ".MI", "Close",, TEXT(WORKDAY(WORKDAY($C9+1,-1), 1), "yyyy-mm-dd"), TEXT(WORKDAY(WORKDAY($C9+1,-1), 1), "yyyy-mm-dd"))) / $D9) - 1), "/") -> 0.0056497175 | F9: =IFERROR(IF(SUM(_xldudf_WISEPRICE($B$8 & ".MI", "Close",, TEXT(WORKDAY(WORKDAY($C9+1,-1), 3), "yyyy-mm-dd"), TEXT(WORKDAY(WORKDAY($C9+1,-1), 3), "yyyy-mm-dd")))=0, "/", (SUM(_xldudf_WISEPRICE($B$8 & ".MI", "Close",, TEXT(WORKDAY(WORKDAY($C9+1,-1), 3), "yyyy-mm-dd"), TEXT(WORKDAY(WORKDAY($C9+1,-1), 3), "yyyy-mm-dd"))) / $D9) - 1), "/") -> 0.047457627 | G9: =IFERROR(IF(SUM(_xldudf_WISEPRICE($B$8 & ".MI", "Close",, TEXT(WORKDAY(WORKDAY($C9+1,-1), 5), "yyyy-mm-dd"), TEXT(WORKDAY(WORKDAY($C9+1,-1), 5), "yyyy-mm-dd")))=0, "/", (SUM(_xldudf_WISEPRICE($B$8 & ".MI", "Close",, TEXT(WORKDAY(WORKDAY($C9+1,-1), 5), "yyyy-mm-dd"), TEXT(WORKDAY(WORKDAY($C9+1,-1), 5), "yyyy-mm-dd"))) / $D9) - 1), "/") -> 0.083239171 | H9: =IFERROR(IF(SUM(_xldudf_WISEPRICE($B$8 & ".MI", "Close",, TEXT(WORKDAY(EDATE(WORKDAY($C9+1,-1), 1)-1, 1), "yyyy-mm-dd"), TEXT(WORKDAY(EDATE(WORKDAY($C9+1,-1), 1)-1, 1), "yyyy-mm-dd")))=0, "/", (SUM(_xldudf_WISEPRICE($B$8 & ".MI", "Close",, TEXT(WORKDAY(EDATE(WORKDAY($C9+1,-1), 1)-1, 1), "yyyy-mm-dd"), TEXT(WORKDAY(EDATE(WORKDAY($C9+1,-1), 1)-1, 1), "yyyy-mm-dd"))) / $D9) - 1), "/") -> 0.1559322
C10: 42185 | D10: =IF(SUM(_xldudf_WISEPRICE($B$8 & ".MI", "Close",, TEXT(WORKDAY($C10+1,-1), "yyyy-mm-dd"), TEXT(WORKDAY($C10+1,-1), "yyyy-mm-dd")))=0, "/", SUM(_xldudf_WISEPRICE($B$8 & ".MI", "Close",, TEXT(WORKDAY($C10+1,-1), "yyyy-mm-dd"), TEXT(WORKDAY($C10+1,-1), "yyyy-mm-dd")))) -> 30.19 | E10: =IFERROR(IF(SUM(_xldudf_WISEPRICE($B$8 & ".MI", "Close",, TEXT(WORKDAY(WORKDAY($C10+1,-1), 1), "yyyy-mm-dd"), TEXT(WORKDAY(WORKDAY($C10+1,-1), 1), "yyyy-mm-dd")))=0, "/", (SUM(_xldudf_WISEPRICE($B$8 & ".MI", "Close",, TEXT(WORKDAY(WORKDAY($C10+1,-1), 1), "yyyy-mm-dd"), TEXT(WORKDAY(WORKDAY($C10+1,-1), 1), "yyyy-mm-dd"))) / $D10) - 1), "/") -> 0.033786022 | F10: =IFERROR(IF(SUM(_xldudf_WISEPRICE($B$8 & ".MI", "Close",, TEXT(WORKDAY(WORKDAY($C10+1,-1), 3), "yyyy-mm-dd"), TEXT(WORKDAY(WORKDAY($C10+1,-1), 3), "yyyy-mm-dd")))=0, "/", (SUM(_xldudf_WISEPRICE($B$8 & ".MI", "Close",, TEXT(WORKDAY(WORKDAY($C10+1,-1), 3), "yyyy-mm-dd"), TEXT(WORKDAY(WORKDAY($C10+1,-1), 3), "yyyy-mm-dd"))) / $D10) - 1), "/") -> 0.0039748261 | G10: =IFERROR(IF(SUM(_xldudf_WISEPRICE($B$8 & ".MI", "Close",, TEXT(WORKDAY(WORKDAY($C10+1,-1), 5), "yyyy-mm-dd"), TEXT(WORKDAY(WORKDAY($C10+1,-1), 5), "yyyy-mm-dd")))=0, "/", (SUM(_xldudf_WISEPRICE($B$8 & ".MI", "Close",, TEXT(WORKDAY(WORKDAY($C10+1,-1), 5), "yyyy-mm-dd"), TEXT(WORKDAY(WORKDAY($C10+1,-1), 5), "yyyy-mm-dd"))) / $D10) - 1), "/") -> -0.093739649 | H10: =IFERROR(IF(SUM(_xldudf_WISEPRICE($B$8 & ".MI", "Close",, TEXT(WORKDAY(EDATE(WORKDAY($C10+1,-1), 1)-1, 1), "yyyy-mm-dd"), TEXT(WORKDAY(EDATE(WORKDAY($C10+1,-1), 1)-1, 1), "yyyy-mm-dd")))=0, "/", (SUM(_xldudf_WISEPRICE($B$8 & ".MI", "Close",, TEXT(WORKDAY(EDATE(WORKDAY($C10+1,-1), 1)-1, 1), "yyyy-mm-dd"), TEXT(WORKDAY(EDATE(WORKDAY($C10+1,-1), 1)-1, 1), "yyyy-mm-dd"))) / $D10) - 1), "/") -> -0.0092745942
C11: 42186 | D11: =IF(SUM(_xldudf_WISEPRICE($B$8 & ".MI", "Close",, TEXT(WORKDAY($C11+1,-1), "yyyy-mm-dd"), TEXT(WORKDAY($C11+1,-1), "yyyy-mm-dd")))=0, "/", SUM(_xldudf_WISEPRICE($B$8 & ".MI", "Close",, TEXT(WORKDAY($C11+1,-1), "yyyy-mm-dd"), TEXT(WORKDAY($C11+1,-1), "yyyy-mm-dd")))) -> 31.21 | E11: =IFERROR(IF(SUM(_xldudf_WISEPRICE($B$8 & ".MI", "Close",, TEXT(WORKDAY(WORKDAY($C11+1,-1), 1), "yyyy-mm-dd"), TEXT(WORKDAY(WORKDAY($C11+1,-1), 1), "yyyy-mm-dd")))=0, "/", (SUM(_xldudf_WISEPRICE($B$8 & ".MI", "Close",, TEXT(WORKDAY(WORKDAY($C11+1,-1), 1), "yyyy-mm-dd"), TEXT(WORKDAY(WORKDAY($C11+1,-1), 1), "yyyy-mm-dd"))) / $D11) - 1), "/") -> -0.019224607 | F11: =IFERROR(IF(SUM(_xldudf_WISEPRICE($B$8 & ".MI", "Close",, TEXT(WORKDAY(WORKDAY($C11+1,-1), 3), "yyyy-mm-dd"), TEXT(WORKDAY(WORKDAY($C11+1,-1), 3), "yyyy-mm-dd")))=0, "/", (SUM(_xldudf_WISEPRICE($B$8 & ".MI", "Close",, TEXT(WORKDAY(WORKDAY($C11+1,-1), 3), "yyyy-mm-dd"), TEXT(WORKDAY(WORKDAY($C11+1,-1), 3), "yyyy-mm-dd"))) / $D11) - 1), "/") -> -0.088112784 | G11: =IFERROR(IF(SUM(_xldudf_WISEPRICE($B$8 & ".MI", "Close",, TEXT(WORKDAY(WORKDAY($C11+1,-1), 5), "yyyy-mm-dd"), TEXT(WORKDAY(WORKDAY($C11+1,-1), 5), "yyyy-mm-dd")))=0, "/", (SUM(_xldudf_WISEPRICE($B$8 & ".MI", "Close",, TEXT(WORKDAY(WORKDAY($C11+1,-1), 5), "yyyy-mm-dd"), TEXT(WORKDAY(WORKDAY($C11+1,-1), 5), "yyyy-mm-dd"))) / $D11) - 1), "/") -> -0.093880167 | H11: =IFERROR(IF(SUM(_xldudf_WISEPRICE($B$8 & ".MI", "Close",, TEXT(WORKDAY(EDATE(WORKDAY($C11+1,-1), 1)-1, 1), "yyyy-mm-dd"), TEXT(WORKDAY(EDATE(WORKDAY($C11+1,-1), 1)-1, 1), "yyyy-mm-dd")))=0, "/", (SUM(_xldudf_WISEPRICE($B$8 & ".MI", "Close",, TEXT(WORKDAY(EDATE(WORKDAY($C11+1,-1), 1)-1, 1), "yyyy-mm-dd"), TEXT(WORKDAY(EDATE(WORKDAY($C11+1,-1), 1)-1, 1), "yyyy-mm-dd"))) / $D11) - 1), "/") -> -0.030438962
C12: 42275 | D12: =IF(SUM(_xldudf_WISEPRICE($B$8 & ".MI", "Close",, TEXT(WORKDAY($C12+1,-1), "yyyy-mm-dd"), TEXT(WORKDAY($C12+1,-1), "yyyy-mm-dd")))=0, "/", SUM(_xldudf_WISEPRICE($B$8 & ".MI", "Close",, TEXT(WORKDAY($C12+1,-1), "yyyy-mm-dd"), TEXT(WORKDAY($C12+1,-1), "yyyy-mm-dd")))) -> 26.98 | E12: =IFERROR(IF(SUM(_xldudf_WISEPRICE($B$8 & ".MI", "Close",, TEXT(WORKDAY(WORKDAY($C12+1,-1), 1), "yyyy-mm-dd"), TEXT(WORKDAY(WORKDAY($C12+1,-1), 1), "yyyy-mm-dd")))=0, "/", (SUM(_xldudf_WISEPRICE($B$8 & ".MI", "Close",, TEXT(WORKDAY(WORKDAY($C12+1,-1), 1), "yyyy-mm-dd"), TEXT(WORKDAY(WORKDAY($C12+1,-1), 1), "yyyy-mm-dd"))) / $D12) - 1), "/") -> 0.00074128984 | F12: =IFERROR(IF(SUM(_xldudf_WISEPRICE($B$8 & ".MI", "Close",, TEXT(WORKDAY(WORKDAY($C12+1,-1), 3), "yyyy-mm-dd"), TEXT(WORKDAY(WORKDAY($C12+1,-1), 3), "yyyy-mm-dd")))=0, "/", (SUM(_xldudf_WISEPRICE($B$8 & ".MI", "Close",, TEXT(WORKDAY(WORKDAY($C12+1,-1), 3), "yyyy-mm-dd"), TEXT(WORKDAY(WORKDAY($C12+1,-1), 3), "yyyy-mm-dd"))) / $D12) - 1), "/") -> 0.038176427 | G12: =IFERROR(IF(SUM(_xldudf_WISEPRICE($B$8 & ".MI", "Close",, TEXT(WORKDAY(WORKDAY($C12+1,-1), 5), "yyyy-mm-dd"), TEXT(WORKDAY(WORKDAY($C12+1,-1), 5), "yyyy-mm-dd")))=0, "/", (SUM(_xldudf_WISEPRICE($B$8 & ".MI", "Close",, TEXT(WORKDAY(WORKDAY($C12+1,-1), 5), "yyyy-mm-dd"), TEXT(WORKDAY(WORKDAY($C12+1,-1), 5), "yyyy-mm-dd"))) / $D12) - 1), "/") -> 0.078947368 | H12: =IFERROR(IF(SUM(_xldudf_WISEPRICE($B$8 & ".MI", "Close",, TEXT(WORKDAY(EDATE(WORKDAY($C12+1,-1), 1)-1, 1), "yyyy-mm-dd"), TEXT(WORKDAY(EDATE(WORKDAY($C12+1,-1), 1)-1, 1), "yyyy-mm-dd")))=0, "/", (SUM(_xldudf_WISEPRICE($B$8 & ".MI", "Close",, TEXT(WORKDAY(EDATE(WORKDAY($C12+1,-1), 1)-1, 1), "yyyy-mm-dd"), TEXT(WORKDAY(EDATE(WORKDAY($C12+1,-1), 1)-1, 1), "yyyy-mm-dd"))) / $D12) - 1), "/") -> 0.11971831
C13: 42355 | D13: =IF(SUM(_xldudf_WISEPRICE($B$8 & ".MI", "Close",, TEXT(WORKDAY($C13+1,-1), "yyyy-mm-dd"), TEXT(WORKDAY($C13+1,-1), "yyyy-mm-dd")))=0, "/", SUM(_xldudf_WISEPRICE($B$8 & ".MI", "Close",, TEXT(WORKDAY($C13+1,-1), "yyyy-mm-dd"), TEXT(WORKDAY($C13+1,-1), "yyyy-mm-dd")))) -> 26.08 | E13: =IFERROR(IF(SUM(_xldudf_WISEPRICE($B$8 & ".MI", "Close",, TEXT(WORKDAY(WORKDAY($C13+1,-1), 1), "yyyy-mm-dd"), TEXT(WORKDAY(WORKDAY($C13+1,-1), 1), "yyyy-mm-dd")))=0, "/", (SUM(_xldudf_WISEPRICE($B$8 & ".MI", "Close",, TEXT(WORKDAY(WORKDAY($C13+1,-1), 1), "yyyy-mm-dd"), TEXT(WORKDAY(WORKDAY($C13+1,-1), 1), "yyyy-mm-dd"))) / $D13) - 1), "/") -> -0.018404908 | F13: =IFERROR(IF(SUM(_xldudf_WISEPRICE($B$8 & ".MI", "Close",, TEXT(WORKDAY(WORKDAY($C13+1,-1), 3), "yyyy-mm-dd"), TEXT(WORKDAY(WORKDAY($C13+1,-1), 3), "yyyy-mm-dd")))=0, "/", (SUM(_xldudf_WISEPRICE($B$8 & ".MI", "Close",, TEXT(WORKDAY(WORKDAY($C13+1,-1), 3), "yyyy-mm-dd"), TEXT(WORKDAY(WORKDAY($C13+1,-1), 3), "yyyy-mm-dd"))) / $D13) - 1), "/") -> -0.014570552 | G13: =IFERROR(IF(SUM(_xldudf_WISEPRICE($B$8 & ".MI", "Close",, TEXT(WORKDAY(WORKDAY($C13+1,-1), 5), "yyyy-mm-dd"), TEXT(WORKDAY(WORKDAY($C13+1,-1), 5), "yyyy-mm-dd")))=0, "/", (SUM(_xldudf_WISEPRICE($B$8 & ".MI", "Close",, TEXT(WORKDAY(WORKDAY($C13+1,-1), 5), "yyyy-mm-dd"), TEXT(WORKDAY(WORKDAY($C13+1,-1), 5), "yyyy-mm-dd"))) / $D13) - 1), "/") -> / | H13: =IFERROR(IF(SUM(_xldudf_WISEPRICE($B$8 & ".MI", "Close",, TEXT(WORKDAY(EDATE(WORKDAY($C13+1,-1), 1)-1, 1), "yyyy-mm-dd"), TEXT(WORKDAY(EDATE(WORKDAY($C13+1,-1), 1)-1, 1), "yyyy-mm-dd")))=0, "/", (SUM(_xldudf_WISEPRICE($B$8 & ".MI", "Close",, TEXT(WORKDAY(EDATE(WORKDAY($C13+1,-1), 1)-1, 1), "yyyy-mm-dd"), TEXT(WORKDAY(EDATE(WORKDAY($C13+1,-1), 1)-1, 1), "yyyy-mm-dd"))) / $D13) - 1), "/") -> -0.20053681
C14: 42717 | D14: =IF(SUM(_xldudf_WISEPRICE($B$8 & ".MI", "Close",, TEXT(WORKDAY($C14+1,-1), "yyyy-mm-dd"), TEXT(WORKDAY($C14+1,-1), "yyyy-mm-dd")))=0, "/", SUM(_xldudf_WISEPRICE($B$8 & ".MI", "Close",, TEXT(WORKDAY($C14+1,-1), "yyyy-mm-dd"), TEXT(WORKDAY($C14+1,-1), "yyyy-mm-dd")))) -> 14.08 | E14: =IFERROR(IF(SUM(_xldudf_WISEPRICE($B$8 & ".MI", "Close",, TEXT(WORKDAY(WORKDAY($C14+1,-1), 1), "yyyy-mm-dd"), TEXT(WORKDAY(WORKDAY($C14+1,-1), 1), "yyyy-mm-dd")))=0, "/", (SUM(_xldudf_WISEPRICE($B$8 & ".MI", "Close",, TEXT(WORKDAY(WORKDAY($C14+1,-1), 1), "yyyy-mm-dd"), TEXT(WORKDAY(WORKDAY($C14+1,-1), 1), "yyyy-mm-dd"))) / $D14) - 1), "/") -> -0.063920455 | F14: =IFERROR(IF(SUM(_xldudf_WISEPRICE($B$8 & ".MI", "Close",, TEXT(WORKDAY(WORKDAY($C14+1,-1), 3), "yyyy-mm-dd"), TEXT(WORKDAY(WORKDAY($C14+1,-1), 3), "yyyy-mm-dd")))=0, "/", (SUM(_xldudf_WISEPRICE($B$8 & ".MI", "Close",, TEXT(WORKDAY(WORKDAY($C14+1,-1), 3), "yyyy-mm-dd"), TEXT(WORKDAY(WORKDAY($C14+1,-1), 3), "yyyy-mm-dd"))) / $D14) - 1), "/") -> 0.022017045 | G14: =IFERROR(IF(SUM(_xldudf_WISEPRICE($B$8 & ".MI", "Close",, TEXT(WORKDAY(WORKDAY($C14+1,-1), 5), "yyyy-mm-dd"), TEXT(WORKDAY(WORKDAY($C14+1,-1), 5), "yyyy-mm-dd")))=0, "/", (SUM(_xldudf_WISEPRICE($B$8 & ".MI", "Close",, TEXT(WORKDAY(WORKDAY($C14+1,-1), 5), "yyyy-mm-dd"), TEXT(WORKDAY(WORKDAY($C14+1,-1), 5), "yyyy-mm-dd"))) / $D14) - 1), "/") -> -0.0042613636 | H14: =IFERROR(IF(SUM(_xldudf_WISEPRICE($B$8 & ".MI", "Close",, TEXT(WORKDAY(EDATE(WORKDAY($C14+1,-1), 1)-1, 1), "yyyy-mm-dd"), TEXT(WORKDAY(EDATE(WORKDAY($C14+1,-1), 1)-1, 1), "yyyy-mm-dd")))=0, "/", (SUM(_xldudf_WISEPRICE($B$8 & ".MI", "Close",, TEXT(WORKDAY(EDATE(WORKDAY($C14+1,-1), 1)-1, 1), "yyyy-mm-dd"), TEXT(WORKDAY(EDATE(WORKDAY($C14+1,-1), 1)-1, 1), "yyyy-mm-dd"))) / $D14) - 1), "/") -> -0.049715909
C15: 43280 | D15: =IF(SUM(_xldudf_WISEPRICE($B$8 & ".MI", "Close",, TEXT(WORKDAY($C15+1,-1), "yyyy-mm-dd"), TEXT(WORKDAY($C15+1,-1), "yyyy-mm-dd")))=0, "/", SUM(_xldudf_WISEPRICE($B$8 & ".MI", "Close",, TEXT(WORKDAY($C15+1,-1), "yyyy-mm-dd"), TEXT(WORKDAY($C15+1,-1), "yyyy-mm-dd")))) -> 14.3 | E15: =IFERROR(IF(SUM(_xldudf_WISEPRICE($B$8 & ".MI", "Close",, TEXT(WORKDAY(WORKDAY($C15+1,-1), 1), "yyyy-mm-dd"), TEXT(WORKDAY(WORKDAY($C15+1,-1), 1), "yyyy-mm-dd")))=0, "/", (SUM(_xldudf_WISEPRICE($B$8 & ".MI", "Close",, TEXT(WORKDAY(WORKDAY($C15+1,-1), 1), "yyyy-mm-dd"), TEXT(WORKDAY(WORKDAY($C15+1,-1), 1), "yyyy-mm-dd"))) / $D15) - 1), "/") -> -0.0041958042 | F15: =IFERROR(IF(SUM(_xldudf_WISEPRICE($B$8 & ".MI", "Close",, TEXT(WORKDAY(WORKDAY($C15+1,-1), 3), "yyyy-mm-dd"), TEXT(WORKDAY(WORKDAY($C15+1,-1), 3), "yyyy-mm-dd")))=0, "/", (SUM(_xldudf_WISEPRICE($B$8 & ".MI", "Close",, TEXT(WORKDAY(WORKDAY($C15+1,-1), 3), "yyyy-mm-dd"), TEXT(WORKDAY(WORKDAY($C15+1,-1), 3), "yyyy-mm-dd"))) / $D15) - 1), "/") -> 0.023776224 | G15: =IFERROR(IF(SUM(_xldudf_WISEPRICE($B$8 & ".MI", "Close",, TEXT(WORKDAY(WORKDAY($C15+1,-1), 5), "yyyy-mm-dd"), TEXT(WORKDAY(WORKDAY($C15+1,-1), 5), "yyyy-mm-dd")))=0, "/", (SUM(_xldudf_WISEPRICE($B$8 & ".MI", "Close",, TEXT(WORKDAY(WORKDAY($C15+1,-1), 5), "yyyy-mm-dd"), TEXT(WORKDAY(WORKDAY($C15+1,-1), 5), "yyyy-mm-dd"))) / $D15) - 1), "/") -> 0.027272727 | H15: =IFERROR(IF(SUM(_xldudf_WISEPRICE($B$8 & ".MI", "Close",, TEXT(WORKDAY(EDATE(WORKDAY($C15+1,-1), 1)-1, 1), "yyyy-mm-dd"), TEXT(WORKDAY(EDATE(WORKDAY($C15+1,-1), 1)-1, 1), "yyyy-mm-dd")))=0, "/", (SUM(_xldudf_WISEPRICE($B$8 & ".MI", "Close",, TEXT(WORKDAY(EDATE(WORKDAY($C15+1,-1), 1)-1, 1), "yyyy-mm-dd"), TEXT(WORKDAY(EDATE(WORKDAY($C15+1,-1), 1)-1, 1), "yyyy-mm-dd"))) / $D15) - 1), "/") -> 0.048951049
C16: 43315 | D16: =IF(SUM(_xldudf_WISEPRICE($B$8 & ".MI", "Close",, TEXT(WORKDAY($C16+1,-1), "yyyy-mm-dd"), TEXT(WORKDAY($C16+1,-1), "yyyy-mm-dd")))=0, "/", SUM(_xldudf_WISEPRICE($B$8 & ".MI", "Close",, TEXT(WORKDAY($C16+1,-1), "yyyy-mm-dd"), TEXT(WORKDAY($C16+1,-1), "yyyy-mm-dd")))) -> 14.39 | E16: =IFERROR(IF(SUM(_xldudf_WISEPRICE($B$8 & ".MI", "Close",, TEXT(WORKDAY(WORKDAY($C16+1,-1), 1), "yyyy-mm-dd"), TEXT(WORKDAY(WORKDAY($C16+1,-1), 1), "yyyy-mm-dd")))=0, "/", (SUM(_xldudf_WISEPRICE($B$8 & ".MI", "Close",, TEXT(WORKDAY(WORKDAY($C16+1,-1), 1), "yyyy-mm-dd"), TEXT(WORKDAY(WORKDAY($C16+1,-1), 1), "yyyy-mm-dd"))) / $D16) - 1), "/") -> -0.00069492703 | F16: =IFERROR(IF(SUM(_xldudf_WISEPRICE($B$8 & ".MI", "Close",, TEXT(WORKDAY(WORKDAY($C16+1,-1), 3), "yyyy-mm-dd"), TEXT(WORKDAY(WORKDAY($C16+1,-1), 3), "yyyy-mm-dd")))=0, "/", (SUM(_xldudf_WISEPRICE($B$8 & ".MI", "Close",, TEXT(WORKDAY(WORKDAY($C16+1,-1), 3), "yyyy-mm-dd"), TEXT(WORKDAY(WORKDAY($C16+1,-1), 3), "yyyy-mm-dd"))) / $D16) - 1), "/") -> 0.024322446 | G16: =IFERROR(IF(SUM(_xldudf_WISEPRICE($B$8 & ".MI", "Close",, TEXT(WORKDAY(WORKDAY($C16+1,-1), 5), "yyyy-mm-dd"), TEXT(WORKDAY(WORKDAY($C16+1,-1), 5), "yyyy-mm-dd")))=0, "/", (SUM(_xldudf_WISEPRICE($B$8 & ".MI", "Close",, TEXT(WORKDAY(WORKDAY($C16+1,-1), 5), "yyyy-mm-dd"), TEXT(WORKDAY(WORKDAY($C16+1,-1), 5), "yyyy-mm-dd"))) / $D16) - 1), "/") -> -0.042390549 | H16: =IFERROR(IF(SUM(_xldudf_WISEPRICE($B$8 & ".MI", "Close",, TEXT(WORKDAY(EDATE(WORKDAY($C16+1,-1), 1)-1, 1), "yyyy-mm-dd"), TEXT(WORKDAY(EDATE(WORKDAY($C16+1,-1), 1)-1, 1), "yyyy-mm-dd")))=0, "/", (SUM(_xldudf_WISEPRICE($B$8 & ".MI", "Close",, TEXT(WORKDAY(EDATE(WORKDAY($C16+1,-1), 1)-1, 1), "yyyy-mm-dd"), TEXT(WORKDAY(EDATE(WORKDAY($C16+1,-1), 1)-1, 1), "yyyy-mm-dd"))) / $D16) - 1), "/") -> -0.13203614
C17: 43371 | D17: =IF(SUM(_xldudf_WISEPRICE($B$8 & ".MI", "Close",, TEXT(WORKDAY($C17+1,-1), "yyyy-mm-dd"), TEXT(WORKDAY($C17+1,-1), "yyyy-mm-dd")))=0, "/", SUM(_xldudf_WISEPRICE($B$8 & ".MI", "Close",, TEXT(WORKDAY($C17+1,-1), "yyyy-mm-dd"), TEXT(WORKDAY($C17+1,-1), "yyyy-mm-dd")))) -> 12.96 | E17: =IFERROR(IF(SUM(_xldudf_WISEPRICE($B$8 & ".MI", "Close",, TEXT(WORKDAY(WORKDAY($C17+1,-1), 1), "yyyy-mm-dd"), TEXT(WORKDAY(WORKDAY($C17+1,-1), 1), "yyyy-mm-dd")))=0, "/", (SUM(_xldudf_WISEPRICE($B$8 & ".MI", "Close",, TEXT(WORKDAY(WORKDAY($C17+1,-1), 1), "yyyy-mm-dd"), TEXT(WORKDAY(WORKDAY($C17+1,-1), 1), "yyyy-mm-dd"))) / $D17) - 1), "/") -> -0.023148148 | F17: =IFERROR(IF(SUM(_xldudf_WISEPRICE($B$8 & ".MI", "Close",, TEXT(WORKDAY(WORKDAY($C17+1,-1), 3), "yyyy-mm-dd"), TEXT(WORKDAY(WORKDAY($C17+1,-1), 3), "yyyy-mm-dd")))=0, "/", (SUM(_xldudf_WISEPRICE($B$8 & ".MI", "Close",, TEXT(WORKDAY(WORKDAY($C17+1,-1), 3), "yyyy-mm-dd"), TEXT(WORKDAY(WORKDAY($C17+1,-1), 3), "yyyy-mm-dd"))) / $D17) - 1), "/") -> -0.033950617 | G17: =IFERROR(IF(SUM(_xldudf_WISEPRICE($B$8 & ".MI", "Close",, TEXT(WORKDAY(WORKDAY($C17+1,-1), 5), "yyyy-mm-dd"), TEXT(WORKDAY(WORKDAY($C17+1,-1), 5), "yyyy-mm-dd")))=0, "/", (SUM(_xldudf_WISEPRICE($B$8 & ".MI", "Close",, TEXT(WORKDAY(WORKDAY($C17+1,-1), 5), "yyyy-mm-dd"), TEXT(WORKDAY(WORKDAY($C17+1,-1), 5), "yyyy-mm-dd"))) / $D17) - 1), "/") -> -0.042438272 | H17: =IFERROR(IF(SUM(_xldudf_WISEPRICE($B$8 & ".MI", "Close",, TEXT(WORKDAY(EDATE(WORKDAY($C17+1,-1), 1)-1, 1), "yyyy-mm-dd"), TEXT(WORKDAY(EDATE(WORKDAY($C17+1,-1), 1)-1, 1), "yyyy-mm-dd")))=0, "/", (SUM(_xldudf_WISEPRICE($B$8 & ".MI", "Close",, TEXT(WORKDAY(EDATE(WORKDAY($C17+1,-1), 1)-1, 1), "yyyy-mm-dd"), TEXT(WORKDAY(EDATE(WORKDAY($C17+1,-1), 1)-1, 1), "yyyy-mm-dd"))) / $D17) - 1), "/") -> -0.11651235
C18: 43445 | D18: =IF(SUM(_xldudf_WISEPRICE($B$8 & ".MI", "Close",, TEXT(WORKDAY($C18+1,-1), "yyyy-mm-dd"), TEXT(WORKDAY($C18+1,-1), "yyyy-mm-dd")))=0, "/", SUM(_xldudf_WISEPRICE($B$8 & ".MI", "Close",, TEXT(WORKDAY($C18+1,-1), "yyyy-mm-dd"), TEXT(WORKDAY($C18+1,-1), "yyyy-mm-dd")))) -> 10.54 | E18: =IFERROR(IF(SUM(_xldudf_WISEPRICE($B$8 & ".MI", "Close",, TEXT(WORKDAY(WORKDAY($C18+1,-1), 1), "yyyy-mm-dd"), TEXT(WORKDAY(WORKDAY($C18+1,-1), 1), "yyyy-mm-dd")))=0, "/", (SUM(_xldudf_WISEPRICE($B$8 & ".MI", "Close",, TEXT(WORKDAY(WORKDAY($C18+1,-1), 1), "yyyy-mm-dd"), TEXT(WORKDAY(WORKDAY($C18+1,-1), 1), "yyyy-mm-dd"))) / $D18) - 1), "/") -> 0.024667932 | F18: =IFERROR(IF(SUM(_xldudf_WISEPRICE($B$8 & ".MI", "Close",, TEXT(WORKDAY(WORKDAY($C18+1,-1), 3), "yyyy-mm-dd"), TEXT(WORKDAY(WORKDAY($C18+1,-1), 3), "yyyy-mm-dd")))=0, "/", (SUM(_xldudf_WISEPRICE($B$8 & ".MI", "Close",, TEXT(WORKDAY(WORKDAY($C18+1,-1), 3), "yyyy-mm-dd"), TEXT(WORKDAY(WORKDAY($C18+1,-1), 3), "yyyy-mm-dd"))) / $D18) - 1), "/") -> 0.025616698 | G18: =IFERROR(IF(SUM(_xldudf_WISEPRICE($B$8 & ".MI", "Close",, TEXT(WORKDAY(WORKDAY($C18+1,-1), 5), "yyyy-mm-dd"), TEXT(WORKDAY(WORKDAY($C18+1,-1), 5), "yyyy-mm-dd")))=0, "/", (SUM(_xldudf_WISEPRICE($B$8 & ".MI", "Close",, TEXT(WORKDAY(WORKDAY($C18+1,-1), 5), "yyyy-mm-dd"), TEXT(WORKDAY(WORKDAY($C18+1,-1), 5), "yyyy-mm-dd"))) / $D18) - 1), "/") -> -0.0066413662 | H18: =IFERROR(IF(SUM(_xldudf_WISEPRICE($B$8 & ".MI", "Close",, TEXT(WORKDAY(EDATE(WORKDAY($C18+1,-1), 1)-1, 1), "yyyy-mm-dd"), TEXT(WORKDAY(EDATE(WORKDAY($C18+1,-1), 1)-1, 1), "yyyy-mm-dd")))=0, "/", (SUM(_xldudf_WISEPRICE($B$8 & ".MI", "Close",, TEXT(WORKDAY(EDATE(WORKDAY($C18+1,-1), 1)-1, 1), "yyyy-mm-dd"), TEXT(WORKDAY(EDATE(WORKDAY($C18+1,-1), 1)-1, 1), "yyyy-mm-dd"))) / $D18) - 1), "/") -> 0.004743833
C19: 43454 | D19: =IF(SUM(_xldudf_WISEPRICE($B$8 & ".MI", "Close",, TEXT(WORKDAY($C19+1,-1), "yyyy-mm-dd"), TEXT(WORKDAY($C19+1,-1), "yyyy-mm-dd")))=0, "/", SUM(_xldudf_WISEPRICE($B$8 & ".MI", "Close",, TEXT(WORKDAY($C19+1,-1), "yyyy-mm-dd"), TEXT(WORKDAY($C19+1,-1), "yyyy-mm-dd")))) -> 10.21 | E19: =IFERROR(IF(SUM(_xldudf_WISEPRICE($B$8 & ".MI", "Close",, TEXT(WORKDAY(WORKDAY($C19+1,-1), 1), "yyyy-mm-dd"), TEXT(WORKDAY(WORKDAY($C19+1,-1), 1), "yyyy-mm-dd")))=0, "/", (SUM(_xldudf_WISEPRICE($B$8 & ".MI", "Close",, TEXT(WORKDAY(WORKDAY($C19+1,-1), 1), "yyyy-mm-dd"), TEXT(WORKDAY(WORKDAY($C19+1,-1), 1), "yyyy-mm-dd"))) / $D19) - 1), "/") -> -0.038197845 | F19: =IFERROR(IF(SUM(_xldudf_WISEPRICE($B$8 & ".MI", "Close",, TEXT(WORKDAY(WORKDAY($C19+1,-1), 3), "yyyy-mm-dd"), TEXT(WORKDAY(WORKDAY($C19+1,-1), 3), "yyyy-mm-dd")))=0, "/", (SUM(_xldudf_WISEPRICE($B$8 & ".MI", "Close",, TEXT(WORKDAY(WORKDAY($C19+1,-1), 3), "yyyy-mm-dd"), TEXT(WORKDAY(WORKDAY($C19+1,-1), 3), "yyyy-mm-dd"))) / $D19) - 1), "/") -> / | G19: =IFERROR(IF(SUM(_xldudf_WISEPRICE($B$8 & ".MI", "Close",, TEXT(WORKDAY(WORKDAY($C19+1,-1), 5), "yyyy-mm-dd"), TEXT(WORKDAY(WORKDAY($C19+1,-1), 5), "yyyy-mm-dd")))=0, "/", (SUM(_xldudf_WISEPRICE($B$8 & ".MI", "Close",, TEXT(WORKDAY(WORKDAY($C19+1,-1), 5), "yyyy-mm-dd"), TEXT(WORKDAY(WORKDAY($C19+1,-1), 5), "yyyy-mm-dd"))) / $D19) - 1), "/") -> -0.059745348 | H19: =IFERROR(IF(SUM(_xldudf_WISEPRICE($B$8 & ".MI", "Close",, TEXT(WORKDAY(EDATE(WORKDAY($C19+1,-1), 1)-1, 1), "yyyy-mm-dd"), TEXT(WORKDAY(EDATE(WORKDAY($C19+1,-1), 1)-1, 1), "yyyy-mm-dd")))=0, "/", (SUM(_xldudf_WISEPRICE($B$8 & ".MI", "Close",, TEXT(WORKDAY(EDATE(WORKDAY($C19+1,-1), 1)-1, 1), "yyyy-mm-dd"), TEXT(WORKDAY(EDATE(WORKDAY($C19+1,-1), 1)-1, 1), "yyyy-mm-dd"))) / $D19) - 1), "/") -> 0.041136141
C20: 43462 | D20: =IF(SUM(_xldudf_WISEPRICE($B$8 & ".MI", "Close",, TEXT(WORKDAY($C20+1,-1), "yyyy-mm-dd"), TEXT(WORKDAY($C20+1,-1), "yyyy-mm-dd")))=0, "/", SUM(_xldudf_WISEPRICE($B$8 & ".MI", "Close",, TEXT(WORKDAY($C20+1,-1), "yyyy-mm-dd"), TEXT(WORKDAY($C20+1,-1), "yyyy-mm-dd")))) -> 9.89 | E20: =IFERROR(IF(SUM(_xldudf_WISEPRICE($B$8 & ".MI", "Close",, TEXT(WORKDAY(WORKDAY($C20+1,-1), 1), "yyyy-mm-dd"), TEXT(WORKDAY(WORKDAY($C20+1,-1), 1), "yyyy-mm-dd")))=0, "/", (SUM(_xldudf_WISEPRICE($B$8 & ".MI", "Close",, TEXT(WORKDAY(WORKDAY($C20+1,-1), 1), "yyyy-mm-dd"), TEXT(WORKDAY(WORKDAY($C20+1,-1), 1), "yyyy-mm-dd"))) / $D20) - 1), "/") -> / | F20: =IFERROR(IF(SUM(_xldudf_WISEPRICE($B$8 & ".MI", "Close",, TEXT(WORKDAY(WORKDAY($C20+1,-1), 3), "yyyy-mm-dd"), TEXT(WORKDAY(WORKDAY($C20+1,-1), 3), "yyyy-mm-dd")))=0, "/", (SUM(_xldudf_WISEPRICE($B$8 & ".MI", "Close",, TEXT(WORKDAY(WORKDAY($C20+1,-1), 3), "yyyy-mm-dd"), TEXT(WORKDAY(WORKDAY($C20+1,-1), 3), "yyyy-mm-dd"))) / $D20) - 1), "/") -> -0.012133468 | G20: =IFERROR(IF(SUM(_xldudf_WISEPRICE($B$8 & ".MI", "Close",, TEXT(WORKDAY(WORKDAY($C20+1,-1), 5), "yyyy-mm-dd"), TEXT(WORKDAY(WORKDAY($C20+1,-1), 5), "yyyy-mm-dd")))=0, "/", (SUM(_xldudf_WISEPRICE($B$8 & ".MI", "Close",, TEXT(WORKDAY(WORKDAY($C20+1,-1), 5), "yyyy-mm-dd"), TEXT(WORKDAY(WORKDAY($C20+1,-1), 5), "yyyy-mm-dd"))) / $D20) - 1), "/") -> 0.032355915 | H20: =IFERROR(IF(SUM(_xldudf_WISEPRICE($B$8 & ".MI", "Close",, TEXT(WORKDAY(EDATE(WORKDAY($C20+1,-1), 1)-1, 1), "yyyy-mm-dd"), TEXT(WORKDAY(EDATE(WORKDAY($C20+1,-1), 1)-1, 1), "yyyy-mm-dd")))=0, "/", (SUM(_xldudf_WISEPRICE($B$8 & ".MI", "Close",, TEXT(WORKDAY(EDATE(WORKDAY($C20+1,-1), 1)-1, 1), "yyyy-mm-dd"), TEXT(WORKDAY(EDATE(WORKDAY($C20+1,-1), 1)-1, 1), "yyyy-mm-dd"))) / $D20) - 1), "/") -> 0.083923155
... C35: 44747 | D35: =IF(SUM(_xldudf_WISEPRICE($B$8 & ".MI", "Close",, TEXT(WORKDAY($C35+1,-1), "yyyy-mm-dd"), TEXT(WORKDAY($C35+1,-1), "yyyy-mm-dd")))=0, "/", SUM(_xldudf_WISEPRICE($B$8 & ".MI", "Close",, TEXT(WORKDAY($C35+1,-1), "yyyy-mm-dd"), TEXT(WORKDAY($C35+1,-1), "yyyy-mm-dd")))) -> 8.83 | E35: =IFERROR(IF(SUM(_xldudf_WISEPRICE($B$8 & ".MI", "Close",, TEXT(WORKDAY(WORKDAY($C35+1,-1), 1), "yyyy-mm-dd"), TEXT(WORKDAY(WORKDAY($C35+1,-1), 1), "yyyy-mm-dd")))=0, "/", (SUM(_xldudf_WISEPRICE($B$8 & ".MI", "Close",, TEXT(WORKDAY(WORKDAY($C35+1,-1), 1), "yyyy-mm-dd"), TEXT(WORKDAY(WORKDAY($C35+1,-1), 1), "yyyy-mm-dd"))) / $D35) - 1), "/") -> 0 | F35: =IFERROR(IF(SUM(_xldudf_WISEPRICE($B$8 & ".MI", "Close",, TEXT(WORKDAY(WORKDAY($C35+1,-1), 3), "yyyy-mm-dd"), TEXT(WORKDAY(WORKDAY($C35+1,-1), 3), "yyyy-mm-dd")))=0, "/", (SUM(_xldudf_WISEPRICE($B$8 & ".MI", "Close",, TEXT(WORKDAY(WORKDAY($C35+1,-1), 3), "yyyy-mm-dd"), TEXT(WORKDAY(WORKDAY($C35+1,-1), 3), "yyyy-mm-dd"))) / $D35) - 1), "/") -> 0.074745187 | G35: =IFERROR(IF(SUM(_xldudf_WISEPRICE($B$8 & ".MI", "Close",, TEXT(WORKDAY(WORKDAY($C35+1,-1), 5), "yyyy-mm-dd"), TEXT(WORKDAY(WORKDAY($C35+1,-1), 5), "yyyy-mm-dd")))=0, "/", (SUM(_xldudf_WISEPRICE($B$8 & ".MI", "Close",, TEXT(WORKDAY(WORKDAY($C35+1,-1), 5), "yyyy-mm-dd"), TEXT(WORKDAY(WORKDAY($C35+1,-1), 5), "yyyy-mm-dd"))) / $D35) - 1), "/") -> 0.030577576 | H35: =IFERROR(IF(SUM(_xldudf_WISEPRICE($B$8 & ".MI", "Close",, TEXT(WORKDAY(EDATE(WORKDAY($C35+1,-1), 1)-1, 1), "yyyy-mm-dd"), TEXT(WORKDAY(EDATE(WORKDAY($C35+1,-1), 1)-1, 1), "yyyy-mm-dd")))=0, "/", (SUM(_xldudf_WISEPRICE($B$8 & ".MI", "Close",, TEXT(WORKDAY(EDATE(WORKDAY($C35+1,-1), 1)-1, 1), "yyyy-mm-dd"), TEXT(WORKDAY(EDATE(WORKDAY($C35+1,-1), 1)-1, 1), "yyyy-mm-dd"))) / $D35) - 1), "/") -> 0.1200453
C36: Average Performance | D36: =_xlfn.AGGREGATE(1,6,D9:D35) -> 14.388148 | E36: =_xlfn.AGGREGATE(1,6,E9:E35) -> -0.0039368676 | F36: =_xlfn.AGGREGATE(1,6,F9:F35) -> 0.0014041793 | G36: =_xlfn.AGGREGATE(1,6,G9:G35) -> -0.015526021 | H36: =_xlfn.AGGREGATE(1,6,H9:H35) -> 0.0060694986
B38: BMPS | D38: Price on event day | E38: Pfm 1 day | F38: Pfm next three days | G38: Pfm 1 week | H38: Pfm 1 month
C39: 42178 | D39: =IF(SUM(_xldudf_WISEPRICE($B$38 & ".MI", "Close",, TEXT(WORKDAY($C39+1,-1), "yyyy-mm-dd"), TEXT(WORKDAY($C39+1,-1), "yyyy-mm-dd")))=0, "/", SUM(_xldudf_WISEPRICE($B$38 & ".MI", "Close",, TEXT(WORKDAY($C39+1,-1), "yyyy-mm-dd"), TEXT(WORKDAY($C39+1,-1), "yyyy-mm-dd")))) -> 19560 | E39: =IFERROR(IF(SUM(_xldudf_WISEPRICE($B$38 & ".MI", "Close",, TEXT(WORKDAY(WORKDAY($C39+1,-1), 1), "yyyy-mm-dd"), TEXT(WORKDAY(WORKDAY($C39+1,-1), 1), "yyyy-mm-dd")))=0, "/", (SUM(_xldudf_WISEPRICE($B$38 & ".MI", "Close",, TEXT(WORKDAY(WORKDAY($C39+1,-1), 1), "yyyy-mm-dd"), TEXT(WORKDAY(WORKDAY($C39+1,-1), 1), "yyyy-mm-dd"))) / $D39) - 1), "/") -> -0.020449898 | F39: =IFERROR(IF(SUM(_xldudf_WISEPRICE($B$38 & ".MI", "Close",, TEXT(WORKDAY(WORKDAY($C39+1,-1), 3), "yyyy-mm-dd"), TEXT(WORKDAY(WORKDAY($C39+1,-1), 3), "yyyy-mm-dd")))=0, "/", (SUM(_xldudf_WISEPRICE($B$38 & ".MI", "Close",, TEXT(WORKDAY(WORKDAY($C39+1,-1), 3), "yyyy-mm-dd"), TEXT(WORKDAY(WORKDAY($C39+1,-1), 3), "yyyy-mm-dd"))) / $D39) - 1), "/") -> 0.0081799591 | G39: =IFERROR(IF(SUM(_xldudf_WISEPRICE($B$38 & ".MI", "Close",, TEXT(WORKDAY(WORKDAY($C39+1,-1), 5), "yyyy-mm-dd"), TEXT(WORKDAY(WORKDAY($C39+1,-1), 5), "yyyy-mm-dd")))=0, "/", (SUM(_xldudf_WISEPRICE($B$38 & ".MI", "Close",, TEXT(WORKDAY(WORKDAY($C39+1,-1), 5), "yyyy-mm-dd"), TEXT(WORKDAY(WORKDAY($C39+1,-1), 5), "yyyy-mm-dd"))) / $D39) - 1), "/") -> -0.10736196 | H39: =IFERROR(IF(SUM(_xldudf_WISEPRICE($B$38 & ".MI", "Close",, TEXT(WORKDAY(EDATE(WORKDAY($C39+1,-1), 1)-1, 1), "yyyy-mm-dd"), TEXT(WORKDAY(EDATE(WORKDAY($C39+1,-1), 1)-1, 1), "yyyy-mm-dd")))=0, "/", (SUM(_xldudf_WISEPRICE($B$38 & ".MI", "Close",, TEXT(WORKDAY(EDATE(WORKDAY($C39+1,-1), 1)-1, 1), "yyyy-mm-dd"), TEXT(WORKDAY(EDATE(WORKDAY($C39+1,-1), 1)-1, 1), "yyyy-mm-dd"))) / $D39) - 1), "/") -> -0.038343558
C40: 42366 | D40: =IF(SUM(_xldudf_WISEPRICE($B$38 & ".MI", "Close",, TEXT(WORKDAY($C40+1,-1), "yyyy-mm-dd"), TEXT(WORKDAY($C40+1,-1), "yyyy-mm-dd")))=0, "/", SUM(_xldudf_WISEPRICE($B$38 & ".MI", "Close",, TEXT(WORKDAY($C40+1,-1), "yyyy-mm-dd"), TEXT(WORKDAY($C40+1,-1), "yyyy-mm-dd")))) -> 12520 | E40: =IFERROR(IF(SUM(_xldudf_WISEPRICE($B$38 & ".MI", "Close",, TEXT(WORKDAY(WORKDAY($C40+1,-1), 1), "yyyy-mm-dd"), TEXT(WORKDAY(WORKDAY($C40+1,-1), 1), "yyyy-mm-dd")))=0, "/", (SUM(_xldudf_WISEPRICE($B$38 & ".MI", "Close",, TEXT(WORKDAY(WORKDAY($C40+1,-1), 1), "yyyy-mm-dd"), TEXT(WORKDAY(WORKDAY($C40+1,-1), 1), "yyyy-mm-dd"))) / $D40) - 1), "/") -> -0.0031948882 | F40: =IFERROR(IF(SUM(_xldudf_WISEPRICE($B$38 & ".MI", "Close",, TEXT(WORKDAY(WORKDAY($C40+1,-1), 3), "yyyy-mm-dd"), TEXT(WORKDAY(WORKDAY($C40+1,-1), 3), "yyyy-mm-dd")))=0, "/", (SUM(_xldudf_WISEPRICE($B$38 & ".MI", "Close",, TEXT(WORKDAY(WORKDAY($C40+1,-1), 3), "yyyy-mm-dd"), TEXT(WORKDAY(WORKDAY($C40+1,-1), 3), "yyyy-mm-dd"))) / $D40) - 1), "/") -> -0.015974441 | G40: =IFERROR(IF(SUM(_xldudf_WISEPRICE($B$38 & ".MI", "Close",, TEXT(WORKDAY(WORKDAY($C40+1,-1), 5), "yyyy-mm-dd"), TEXT(WORKDAY(WORKDAY($C40+1,-1), 5), "yyyy-mm-dd")))=0, "/", (SUM(_xldudf_WISEPRICE($B$38 & ".MI", "Close",, TEXT(WORKDAY(WORKDAY($C40+1,-1), 5), "yyyy-mm-dd"), TEXT(WORKDAY(WORKDAY($C40+1,-1), 5), "yyyy-mm-dd"))) / $D40) - 1), "/") -> -0.06629393 | H40: =IFERROR(IF(SUM(_xldudf_WISEPRICE($B$38 & ".MI", "Close",, TEXT(WORKDAY(EDATE(WORKDAY($C40+1,-1), 1)-1, 1), "yyyy-mm-dd"), TEXT(WORKDAY(EDATE(WORKDAY($C40+1,-1), 1)-1, 1), "yyyy-mm-dd")))=0, "/", (SUM(_xldudf_WISEPRICE($B$38 & ".MI", "Close",, TEXT(WORKDAY(EDATE(WORKDAY($C40+1,-1), 1)-1, 1), "yyyy-mm-dd"), TEXT(WORKDAY(EDATE(WORKDAY($C40+1,-1), 1)-1, 1), "yyyy-mm-dd"))) / $D40) - 1), "/") -> -0.47683706
C41: 43190 | D41: =IF(SUM(_xldudf_WISEPRICE($B$38 & ".MI", "Close",, TEXT(WORKDAY($C41+1,-1), "yyyy-mm-dd"), TEXT(WORKDAY($C41+1,-1), "yyyy-mm-dd")))=0, "/", SUM(_xldudf_WISEPRICE($B$38 & ".MI", "Close",, TEXT(WORKDAY($C41+1,-1), "yyyy-mm-dd"), TEXT(WORKDAY($C41+1,-1), "yyyy-mm-dd")))) -> / | E41: =IFERROR(IF(SUM(_xldudf_WISEPRICE($B$38 & ".MI", "Close",, TEXT(WORKDAY(WORKDAY($C41+1,-1), 1), "yyyy-mm-dd"), TEXT(WORKDAY(WORKDAY($C41+1,-1), 1), "yyyy-mm-dd")))=0, "/", (SUM(_xldudf_WISEPRICE($B$38 & ".MI", "Close",, TEXT(WORKDAY(WORKDAY($C41+1,-1), 1), "yyyy-mm-dd"), TEXT(WORKDAY(WORKDAY($C41+1,-1), 1), "yyyy-mm-dd"))) / $D41) - 1), "/") -> / | F41: =IFERROR(IF(SUM(_xldudf_WISEPRICE($B$38 & ".MI", "Close",, TEXT(WORKDAY(WORKDAY($C41+1,-1), 3), "yyyy-mm-dd"), TEXT(WORKDAY(WORKDAY($C41+1,-1), 3), "yyyy-mm-dd")))=0, "/", (SUM(_xldudf_WISEPRICE($B$38 & ".MI", "Close",, TEXT(WORKDAY(WORKDAY($C41+1,-1), 3), "yyyy-mm-dd"), TEXT(WORKDAY(WORKDAY($C41+1,-1), 3), "yyyy-mm-dd"))) / $D41) - 1), "/") -> / | G41: =IFERROR(IF(SUM(_xldudf_WISEPRICE($B$38 & ".MI", "Close",, TEXT(WORKDAY(WORKDAY($C41+1,-1), 5), "yyyy-mm-dd"), TEXT(WORKDAY(WORKDAY($C41+1,-1), 5), "yyyy-mm-dd")))=0, "/", (SUM(_xldudf_WISEPRICE($B$38 & ".MI", "Close",, TEXT(WORKDAY(WORKDAY($C41+1,-1), 5), "yyyy-mm-dd"), TEXT(WORKDAY(WORKDAY($C41+1,-1), 5), "yyyy-mm-dd"))) / $D41) - 1), "/") -> / | H41: =IFERROR(IF(SUM(_xldudf_WISEPRICE($B$38 & ".MI", "Close",, TEXT(WORKDAY(EDATE(WORKDAY($C41+1,-1), 1)-1, 1), "yyyy-mm-dd"), TEXT(WORKDAY(EDATE(WORKDAY($C41+1,-1), 1)-1, 1), "yyyy-mm-dd")))=0, "/", (SUM(_xldudf_WISEPRICE($B$38 & ".MI", "Close",, TEXT(WORKDAY(EDATE(WORKDAY($C41+1,-1), 1)-1, 1), "yyyy-mm-dd"), TEXT(WORKDAY(EDATE(WORKDAY($C41+1,-1), 1)-1, 1), "yyyy-mm-dd"))) / $D41) - 1), "/") -> /
C42: 43281 | D42: =IF(SUM(_xldudf_WISEPRICE($B$38 & ".MI", "Close",, TEXT(WORKDAY($C42+1,-1), "yyyy-mm-dd"), TEXT(WORKDAY($C42+1,-1), "yyyy-mm-dd")))=0, "/", SUM(_xldudf_WISEPRICE($B$38 & ".MI", "Close",, TEXT(WORKDAY($C42+1,-1), "yyyy-mm-dd"), TEXT(WORKDAY($C42+1,-1), "yyyy-mm-dd")))) -> 246.5 | E42: =IFERROR(IF(SUM(_xldudf_WISEPRICE($B$38 & ".MI", "Close",, TEXT(WORKDAY(WORKDAY($C42+1,-1), 1), "yyyy-mm-dd"), TEXT(WORKDAY(WORKDAY($C42+1,-1), 1), "yyyy-mm-dd")))=0, "/", (SUM(_xldudf_WISEPRICE($B$38 & ".MI", "Close",, TEXT(WORKDAY(WORKDAY($C42+1,-1), 1), "yyyy-mm-dd"), TEXT(WORKDAY(WORKDAY($C42+1,-1), 1), "yyyy-mm-dd"))) / $D42) - 1), "/") -> 0.0012170507 | F42: =IFERROR(IF(SUM(_xldudf_WISEPRICE($B$38 & ".MI", "Close",, TEXT(WORKDAY(WORKDAY($C42+1,-1), 3), "yyyy-mm-dd"), TEXT(WORKDAY(WORKDAY($C42+1,-1), 3), "yyyy-mm-dd")))=0, "/", (SUM(_xldudf_WISEPRICE($B$38 & ".MI", "Close",, TEXT(WORKDAY(WORKDAY($C42+1,-1), 3), "yyyy-mm-dd"), TEXT(WORKDAY(WORKDAY($C42+1,-1), 3), "yyyy-mm-dd"))) / $D42) - 1), "/") -> -0.0036510913 | G42: =IFERROR(IF(SUM(_xldudf_WISEPRICE($B$38 & ".MI", "Close",, TEXT(WORKDAY(WORKDAY($C42+1,-1), 5), "yyyy-mm-dd"), TEXT(WORKDAY(WORKDAY($C42+1,-1), 5), "yyyy-mm-dd")))=0, "/", (SUM(_xldudf_WISEPRICE($B$38 & ".MI", "Close",, TEXT(WORKDAY(WORKDAY($C42+1,-1), 5), "yyyy-mm-dd"), TEXT(WORKDAY(WORKDAY($C42+1,-1), 5), "yyyy-mm-dd"))) / $D42) - 1), "/") -> -0.0056794888 | H42: =IFERROR(IF(SUM(_xldudf_WISEPRICE($B$38 & ".MI", "Close",, TEXT(WORKDAY(EDATE(WORKDAY($C42+1,-1), 1)-1, 1), "yyyy-mm-dd"), TEXT(WORKDAY(EDATE(WORKDAY($C42+1,-1), 1)-1, 1), "yyyy-mm-dd")))=0, "/", (SUM(_xldudf_WISEPRICE($B$38 & ".MI", "Close",, TEXT(WORKDAY(EDATE(WORKDAY($C42+1,-1), 1)-1, 1), "yyyy-mm-dd"), TEXT(WORKDAY(EDATE(WORKDAY($C42+1,-1), 1)-1, 1), "yyyy-mm-dd"))) / $D42) - 1), "/") -> 0.064908722
C43: 43313 | D43: =IF(SUM(_xldudf_WISEPRICE($B$38 & ".MI", "Close",, TEXT(WORKDAY($C43+1,-1), "yyyy-mm-dd"), TEXT(WORKDAY($C43+1,-1), "yyyy-mm-dd")))=0, "/", SUM(_xldudf_WISEPRICE($B$38 & ".MI", "Close",, TEXT(WORKDAY($C43+1,-1), "yyyy-mm-dd"), TEXT(WORKDAY($C43+1,-1), "yyyy-mm-dd")))) -> 260 | E43: =IFERROR(IF(SUM(_xldudf_WISEPRICE($B$38 & ".MI", "Close",, TEXT(WORKDAY(WORKDAY($C43+1,-1), 1), "yyyy-mm-dd"), TEXT(WORKDAY(WORKDAY($C43+1,-1), 1), "yyyy-mm-dd")))=0, "/", (SUM(_xldudf_WISEPRICE($B$38 & ".MI", "Close",, TEXT(WORKDAY(WORKDAY($C43+1,-1), 1), "yyyy-mm-dd"), TEXT(WORKDAY(WORKDAY($C43+1,-1), 1), "yyyy-mm-dd"))) / $D43) - 1), "/") -> -0.048846142 | F43: =IFERROR(IF(SUM(_xldudf_WISEPRICE($B$38 & ".MI", "Close",, TEXT(WORKDAY(WORKDAY($C43+1,-1), 3), "yyyy-mm-dd"), TEXT(WORKDAY(WORKDAY($C43+1,-1), 3), "yyyy-mm-dd")))=0, "/", (SUM(_xldudf_WISEPRICE($B$38 & ".MI", "Close",, TEXT(WORKDAY(WORKDAY($C43+1,-1), 3), "yyyy-mm-dd"), TEXT(WORKDAY(WORKDAY($C43+1,-1), 3), "yyyy-mm-dd"))) / $D43) - 1), "/") -> -0.088846177 | G43: =IFERROR(IF(SUM(_xldudf_WISEPRICE($B$38 & ".MI", "Close",, TEXT(WORKDAY(WORKDAY($C43+1,-1), 5), "yyyy-mm-dd"), TEXT(WORKDAY(WORKDAY($C43+1,-1), 5), "yyyy-mm-dd")))=0, "/", (SUM(_xldudf_WISEPRICE($B$38 & ".MI", "Close",, TEXT(WORKDAY(WORKDAY($C43+1,-1), 5), "yyyy-mm-dd"), TEXT(WORKDAY(WORKDAY($C43+1,-1), 5), "yyyy-mm-dd"))) / $D43) - 1), "/") -> -0.069999988 | H43: =IFERROR(IF(SUM(_xldudf_WISEPRICE($B$38 & ".MI", "Close",, TEXT(WORKDAY(EDATE(WORKDAY($C43+1,-1), 1)-1, 1), "yyyy-mm-dd"), TEXT(WORKDAY(EDATE(WORKDAY($C43+1,-1), 1)-1, 1), "yyyy-mm-dd")))=0, "/", (SUM(_xldudf_WISEPRICE($B$38 & ".MI", "Close",, TEXT(WORKDAY(EDATE(WORKDAY($C43+1,-1), 1)-1, 1), "yyyy-mm-dd"), TEXT(WORKDAY(EDATE(WORKDAY($C43+1,-1), 1)-1, 1), "yyyy-mm-dd"))) / $D43) - 1), "/") -> -0.17846152
C44: 43454 | D44: =IF(SUM(_xldudf_WISEPRICE($B$38 & ".MI", "Close",, TEXT(WORKDAY($C44+1,-1), "yyyy-mm-dd"), TEXT(WORKDAY($C44+1,-1), "yyyy-mm-dd")))=0, "/", SUM(_xldudf_WISEPRICE($B$38 & ".MI", "Close",, TEXT(WORKDAY($C44+1,-1), "yyyy-mm-dd"), TEXT(WORKDAY($C44+1,-1), "yyyy-mm-dd")))) -> 149.95 | E44: =IFERROR(IF(SUM(_xldudf_WISEPRICE($B$38 & ".MI", "Close",, TEXT(WORKDAY(WORKDAY($C44+1,-1), 1), "yyyy-mm-dd"), TEXT(WORKDAY(WORKDAY($C44+1,-1), 1), "yyyy-mm-dd")))=0, "/", (SUM(_xldudf_WISEPRICE($B$38 & ".MI", "Close",, TEXT(WORKDAY(WORKDAY($C44+1,-1), 1), "yyyy-mm-dd"), TEXT(WORKDAY(WORKDAY($C44+1,-1), 1), "yyyy-mm-dd"))) / $D44) - 1), "/") -> 0.026342095 | F44: =IFERROR(IF(SUM(_xldudf_WISEPRICE($B$38 & ".MI", "Close",, TEXT(WORKDAY(WORKDAY($C44+1,-1), 3), "yyyy-mm-dd"), TEXT(WORKDAY(WORKDAY($C44+1,-1), 3), "yyyy-mm-dd")))=0, "/", (SUM(_xldudf_WISEPRICE($B$38 & ".MI", "Close",, TEXT(WORKDAY(WORKDAY($C44+1,-1), 3), "yyyy-mm-dd"), TEXT(WORKDAY(WORKDAY($C44+1,-1), 3), "yyyy-mm-dd"))) / $D44) - 1), "/") -> / | G44: =IFERROR(IF(SUM(_xldudf_WISEPRICE($B$38 & ".MI", "Close",, TEXT(WORKDAY(WORKDAY($C44+1,-1), 5), "yyyy-mm-dd"), TEXT(WORKDAY(WORKDAY($C44+1,-1), 5), "yyyy-mm-dd")))=0, "/", (SUM(_xldudf_WISEPRICE($B$38 & ".MI", "Close",, TEXT(WORKDAY(WORKDAY($C44+1,-1), 5), "yyyy-mm-dd"), TEXT(WORKDAY(WORKDAY($C44+1,-1), 5), "yyyy-mm-dd"))) / $D44) - 1), "/") -> -0.010003335 | H44: =IFERROR(IF(SUM(_xldudf_WISEPRICE($B$38 & ".MI", "Close",, TEXT(WORKDAY(EDATE(WORKDAY($C44+1,-1), 1)-1, 1), "yyyy-mm-dd"), TEXT(WORKDAY(EDATE(WORKDAY($C44+1,-1), 1)-1, 1), "yyyy-mm-dd")))=0, "/", (SUM(_xldudf_WISEPRICE($B$38 & ".MI", "Close",, TEXT(WORKDAY(EDATE(WORKDAY($C44+1,-1), 1)-1, 1), "yyyy-mm-dd"), TEXT(WORKDAY(EDATE(WORKDAY($C44+1,-1), 1)-1, 1), "yyyy-mm-dd"))) / $D44) - 1), "/") -> -0.18672891
C45: 43497 | D45: =IF(SUM(_xldudf_WISEPRICE($B$38 & ".MI", "Close",, TEXT(WORKDAY($C45+1,-1), "yyyy-mm-dd"), TEXT(WORKDAY($C45+1,-1), "yyyy-mm-dd")))=0, "/", SUM(_xldudf_WISEPRICE($B$38 & ".MI", "Close",, TEXT(WORKDAY($C45+1,-1), "yyyy-mm-dd"), TEXT(WORKDAY($C45+1,-1), "yyyy-mm-dd")))) -> 120.85 | E45: =IFERROR(IF(SUM(_xldudf_WISEPRICE($B$38 & ".MI", "Close",, TEXT(WORKDAY(WORKDAY($C45+1,-1), 1), "yyyy-mm-dd"), TEXT(WORKDAY(WORKDAY($C45+1,-1), 1), "yyyy-mm-dd")))=0, "/", (SUM(_xldudf_WISEPRICE($B$38 & ".MI", "Close",, TEXT(WORKDAY(WORKDAY($C45+1,-1), 1), "yyyy-mm-dd"), TEXT(WORKDAY(WORKDAY($C45+1,-1), 1), "yyyy-mm-dd"))) / $D45) - 1), "/") -> -0.0091021764 | F45: =IFERROR(IF(SUM(_xldudf_WISEPRICE($B$38 & ".MI", "Close",, TEXT(WORKDAY(WORKDAY($C45+1,-1), 3), "yyyy-mm-dd"), TEXT(WORKDAY(WORKDAY($C45+1,-1), 3), "yyyy-mm-dd")))=0, "/", (SUM(_xldudf_WISEPRICE($B$38 & ".MI", "Close",, TEXT(WORKDAY(WORKDAY($C45+1,-1), 3), "yyyy-mm-dd"), TEXT(WORKDAY(WORKDAY($C45+1,-1), 3), "yyyy-mm-dd"))) / $D45) - 1), "/") -> 0.024410468 | G45: =IFERROR(IF(SUM(_xldudf_WISEPRICE($B$38 & ".MI", "Close",, TEXT(WORKDAY(WORKDAY($C45+1,-1), 5), "yyyy-mm-dd"), TEXT(WORKDAY(WORKDAY($C45+1,-1), 5), "yyyy-mm-dd")))=0, "/", (SUM(_xldudf_WISEPRICE($B$38 & ".MI", "Close",, TEXT(WORKDAY(WORKDAY($C45+1,-1), 5), "yyyy-mm-dd"), TEXT(WORKDAY(WORKDAY($C45+1,-1), 5), "yyyy-mm-dd"))) / $D45) - 1), "/") -> 0.018204427 | H45: =IFERROR(IF(SUM(_xldudf_WISEPRICE($B$38 & ".MI", "Close",, TEXT(WORKDAY(EDATE(WORKDAY($C45+1,-1), 1)-1, 1), "yyyy-mm-dd"), TEXT(WORKDAY(EDATE(WORKDAY($C45+1,-1), 1)-1, 1), "yyyy-mm-dd")))=0, "/", (SUM(_xldudf_WISEPRICE($B$38 & ".MI", "Close",, TEXT(WORKDAY(EDATE(WORKDAY($C45+1,-1), 1)-1, 1), "yyyy-mm-dd"), TEXT(WORKDAY(EDATE(WORKDAY($C45+1,-1), 1)-1, 1), "yyyy-mm-dd"))) / $D45) - 1), "/") -> 0.11129504
