Workbook

Sheet Instructions
A1: BUYBACK ANALYSIS - European Markets
A3: Project: Do Buybacks Explain European Stock Returns Better Than Earnings Growth?
A5: INDEXES COVERED:
A6: • FTSE MIB (Italy) — 41 companies
A7: • DAX 40 (Germany) — 40 companies
A8: • CAC 40 (France) — 40 companies
A9: • IBEX 35 (Spain) — 35 companies
A10: Total: 156 companies
A12: SHEETS:
A13: 1. Net Income — Annual net income in € millions
A14: 2. Avg Shares Outstanding — Weighted average shares outstanding in millions
A15: 3. Stock Price Return — Annual price return (excluding dividends), as decimal (e.g. 0.15 = 15%)
... A34: • Stellantis and STMicroelectronics appear in both Italy and France indexes — handle as needed

Sheet Net Income
A1: Net Income (€ millions)
A2: Values to be filled manually. Blue cells = data input fields.
A3: Ticker | B3: Company | C3: Country | D3: Index | E3: 2015 | F3: 2016 | G3: 2017 | H3: 2018 | I3: 2019 | J3: 2020 | K3: 2021 | L3: 2022 | M3: 2023 | N3: 2024
A4: FTSE MIB
A5: A2A.MI | B5: A2A | C5: Italy | D5: FTSE MIB | E5: 73000000 | F5: 224000000 | G5: 293000000 | H5: 344000000 | I5: 389000000 | J5: 364000000 | K5: 504000000 | L5: 401000000 | M5: 659000000 | N5: 864000000
A6: AMP.MI | B6: Amplifon | C6: Italy | D6: FTSE MIB | E6: 46805000 | F6: 63620000 | G6: 100578000 | H6: 100443000 | I6: 108666000 | J6: 101004000 | K6: 157785000 | L6: 178525000 | M6: 155139000 | N6: 145374000
A7: G.MI | B7: Assicurazioni Generali | C7: Italy | D7: FTSE MIB | E7: 2030000000 | F7: 2081000000 | G7: 2110000000 | H7: 2309000000 | I7: 2670000000 | J7: 1744000000 | K7: 2847000000 | L7: 2912000000 | M7: 3747000000 | N7: 3724000000
A8: AZM.MI | B8: Azimut Holding | C8: Italy | D8: FTSE MIB | E8: 247421000 | F8: 172685000 | G8: 214786000 | H8: 122146000 | I8: 370011000 | J8: 381690000 | K8: 605457000 | L8: 406461000 | M8: 434567000 | N8: 576165000
A9: BGN.MI | B9: Banca Generali | C9: Italy | D9: FTSE MIB | E9: 203559000 | F9: 155894000 | G9: 204105000 | H9: 180126000 | I9: 272139000 | J9: 274919000 | K9: 323103000 | L9: 213034000 | M9: 326136000 | N9: 431225000
A10: BMED.MI | B10: Banca Mediolanum | C10: Italy | D10: FTSE MIB | E10: 438613000 | F10: 393527000 | G10: 379992000 | H10: 255710000 | I10: 565432000 | J10: 434462000 | K10: 713055000 | L10: 506829000 | M10: 821870000 | N10: 1119629000
A11: BAMI.MI | B11: Banco BPM | C11: Italy | D11: FTSE MIB | E11: 430073000 | F11: -1681660000 | G11: 2616362000 | H11: -59432000 | I11: 797001000 | J11: 20880000 | K11: 569068000 | L11: 685047000 | M11: 1264453000 | N11: 1920393000
A12: BPE.MI | B12: BPER Banca | C12: Italy | D12: FTSE MIB | E12: 220661000 | F12: 14299000 | G12: 176438000 | H12: 401953000 | I12: 379583000 | J12: 236925000 | K12: 525123000 | L12: 1448975000 | M12: 1519496000 | N12: 1402649000
A13: BZU.MI | B13: Buzzi | C13: Italy | D13: FTSE MIB | E13: 125330000 | F13: 145866000 | G13: 391622000 | H13: 382133000 | I13: 385671000 | J13: 560246000 | K13: 541903000 | L13: 458786000 | M13: 966545000 | N13: 942316000
A14: CPR.MI | B14: Campari Group | C14: Italy | D14: FTSE MIB | E14: 175400000 | F14: 166300000 | G14: 356400000 | H14: 296300000 | I14: 308400000 | J14: 187900000 | K14: 284800000 | L14: 333000000 | M14: 330500000 | N14: 201600000
A15: CNHI.MI | B15: CNH Industrial | C15: Italy | D15: FTSE MIB | E15: 253000000 | F15: -252000000 | G15: 295000000 | H15: 1068000000 | I15: 1422000000 | J15: -455000000 | K15: 1723000000 | L15: 2029000000 | M15: 2275000000
A16: DIA.MI | B16: DiaSorin | C16: Italy | D16: FTSE MIB | E16: 100420000 | F16: 112383000 | G16: 139878000 | H16: 158128000 | I16: 175735000 | J16: 247871000 | K16: 310968000 | L16: 240907000 | M16: 159849000 | N16: 188105000
A17: ENEL.MI | B17: Enel | C17: Italy | D17: FTSE MIB | E17: 2196000000 | F17: 2570000000 | G17: 3779000000 | H17: 4789000000 | I17: 2174000000 | J17: 2610000000 | K17: 3189000000 | L17: 1682000000 | M17: 3438000000 | N17: 7016000000
A18: ENI.MI | B18: Eni | C18: Italy | D18: FTSE MIB | E18: -8778000000 | F18: -1464000000 | G18: 3374000000 | H18: 4126000000 | I18: 148000000 | J18: -8635000000 | K18: 5821000000 | L18: 13887000000 | M18: 4771000000 | N18: 2624000000
A19: EXO.MI | B19: Exor | C19: Italy | D19: FTSE MIB
A20: RACE.MI | B20: Ferrari | C20: Italy | D20: FTSE MIB | G20: 535393000 | H20: 784678000 | I20: 695818000 | J20: 607817000 | K20: 830767000 | L20: 932614000 | M20: 1252048000 | N20: 1521877000
A21: FBK.MI | B21: FinecoBank | C21: Italy | D21: FTSE MIB | E21: 191052791 | F21: 211843794 | G21: 214120370 | H21: 241219000 | I21: 288365000 | J21: 323571000 | K21: 380711000 | L21: 428505000 | M21: 609101000 | N21: 652285000
A22: HER.MI | B22: Hera Group | C22: Italy | D22: FTSE MIB | E22: 180000000 | F22: 207300000 | G22: 251400000 | H22: 281900000 | I22: 385700000 | J22: 302700000 | K22: 333500000 | L22: 255200000 | M22: 441400000 | N22: 494500000
A23: INW.MI | B23: Infrastrutture Wireless Italiane | C23: Italy | D23: FTSE MIB | F23: 97924833 | G23: 126740774 | H23: 140760895 | I23: 139313769 | J23: 156666767 | K23: 191395676 | L23: 293339000 | M23: 339497000 | N23: 353900000
A24: IP.MI | B24: Interpump Group | C24: Italy | D24: FTSE MIB | E24: 117639000 | F24: 93850000 | G24: 134442000 | H24: 172905000 | I24: 179170000 | J24: 170980000 | K24: 195882000 | L24: 266497000 | M24: 274269000 | N24: 227063000
A25: ISP.MI | B25: Intesa Sanpaolo | C25: Italy | D25: FTSE MIB | E25: 2739000000 | F25: 3111000000 | G25: 7316000000 | H25: 4050000000 | I25: 4182000000 | J25: 3277000000 | K25: 4185000000 | L25: 4379000000 | M25: 7724000000 | N25: 8666000000
A26: IG.MI | B26: Italgas | C26: Italy | D26: FTSE MIB | G26: 292766000 | H26: 313695000 | I26: 417238000 | J26: 384626000 | K26: 362813000 | L26: 407288000 | M26: 439568000 | N26: 478854000
A27: IVG.MI | B27: Iveco | C27: Italy | D27: FTSE MIB | M27: 218000000 | N27: 349000000
A28: LDO.MI | B28: Leonardo | C28: Italy | D28: FTSE MIB | E28: 487000000 | F28: 505000000 | G28: 277000000 | H28: 509000000 | I28: 821000000 | J28: 241000000 | K28: 586000000 | L28: 927000000 | M28: 658000000 | N28: 1074000000
A29: MB.MI | B29: Mediobanca | C29: Italy | D29: FTSE MIB | E29: 589751000 | F29: 604550000 | G29: 750200000 | H29: 863920000 | I29: 823025000 | J29: 600382000 | K29: 807576000 | L29: 906977000 | M29: 1025986000 | N29: 1273382000
A30: MONC.MI | B30: Moncler | C30: Italy | D30: FTSE MIB | E30: 167863000 | F30: 196043000 | G30: 249688000 | H30: 332395000 | I30: 358685000 | J30: 300351000 | K30: 393533000 | L30: 606697000 | M30: 611931000 | N30: 639596000
A31: NEXI.MI | B31: Nexi | C31: Italy | D31: FTSE MIB | J31: 127926000 | K31: 37729000 | L31: 140023000 | M31: -1027145000 | N31: 167361000
A32: PIRC.MI | B32: Pirelli | C32: Italy | D32: FTSE MIB | H32: 431606000 | I32: 438134000 | J32: 42673000 | K32: 302796000 | L32: 417760000 | M32: 479080000 | N32: 467981000
A33: PST.MI | B33: Poste Italiane | C33: Italy | D33: FTSE MIB | F33: 622000000 | G33: 689000000 | H33: 1399000000 | I33: 1342000000 | J33: 1207000000 | K33: 1578000000 | L33: 1578000000 | M33: 1922000000 | N33: 1994000000
A34: PRY.MI | B34: Prysmian Group | C34: Italy | D34: FTSE MIB | E34: 214000000 | F34: 246000000 | G34: 227000000 | H34: 130000000 | I34: 292000000 | J34: 178000000 | K34: 308000000 | L34: 504000000 | M34: 529000000 | N34: 729000000
A35: SPM.MI | B35: Saipem | C35: Italy | D35: FTSE MIB | E35: -806000000 | F35: -2087000000 | G35: -328000000 | H35: -472000000 | I35: 98000000 | J35: -1117000000 | K35: -2467000000 | L35: -315000000 | M35: 179000000 | N35: 306000000
A36: SRG.MI | B36: Snam | C36: Italy | D36: FTSE MIB | E36: 1238000000 | F36: 861000000 | G36: 897000000 | H36: 960000000 | I36: 1090000000 | J36: 1101000000 | K36: 1496000000 | L36: 671000000 | M36: 1135000000 | N36: 1259000000
A37: STLAM.MI | B37: Stellantis | C37: Italy | D37: FTSE MIB | E37: 334000000 | F37: 1803000000 | G37: 3491000000 | H37: 3608000000 | I37: 6622000000 | J37: 29000000 | K37: 14200000000 | L37: 16799000000 | M37: 18596000000 | N37: 5473000000
A38: STMMI.MI | B38: STMicroelectronics | C38: Italy | D38: FTSE MIB | E38: 175000000 | F38: 121000000 | G38: 218000000 | H38: 1629000000 | I38: 1032000000 | J38: 1106000000 | K38: 2000000000 | L38: 3960000000 | M38: 3985000000 | N38: 1557000000
A39: TEN.MI | B39: Tenaris | C39: Italy | D39: FTSE MIB | E39: -80162000 | F39: 55298000 | G39: 544737000 | H39: 876063000 | I39: 742686000 | J39: -642417000 | K39: 1100191000 | L39: 2553280000 | M39: 3918065000 | N39: 2036445000
A40: TRN.MI | B40: Terna | C40: Italy | D40: FTSE MIB | E40: 595500000 | F40: 633100000 | G40: 688300000 | H40: 706600000 | I40: 757300000 | J40: 785500000 | K40: 789400000 | L40: 857000000 | M40: 885400000 | N40: 1061900000
...

Sheet Avg Shares Outstanding
A1: Weighted Avg Shares Outstanding (millions)
A2: Values to be filled manually. Blue cells = data input fields.
A3: Ticker | B3: Company | C3: Country | D3: Index | E3: 2015 | F3: 2016 | G3: 2017 | H3: 2018 | I3: 2019 | J3: 2020 | K3: 2021 | L3: 2022 | M3: 2023 | N3: 2024
A4: FTSE MIB
A5: A2A.MI | B5: A2A | C5: Italy | D5: FTSE MIB | E5: 3105987668 | F5: 3109183856 | G5: 3109183856 | H5: 3109183856 | I5: 3109183856 | J5: 3109183856 | K5: 3073686277 | L5: 3073686277 | M5: 3132905277 | N5: 3132704859
A6: AMP.MI | B6: Amplifon | C6: Italy | D6: FTSE MIB | E6: 218047951 | F6: 219322356 | G6: 219095844 | H6: 219758444 | I6: 221863663 | J6: 223797671 | K6: 224823927 | L6: 224363318 | M6: 225463566 | N6: 225792000
A7: G.MI | B7: Assicurazioni Generali | C7: Italy | D7: FTSE MIB | E7: 1556428701 | F7: 1558512070 | G7: 1560771499 | H7: 1563742903 | I7: 1567927100 | J7: 1569448327 | K7: 1573173478 | L7: 1570223226 | M7: 1541766041 | N7: 1538691000
A8: AZM.MI | B8: Azimut Holding | C8: Italy | D8: FTSE MIB | E8: 142754548 | F8: 142746313 | G8: 133420894 | H8: 138134324 | I8: 140110863 | J8: 138590424 | K8: 139154500 | L8: 139226158 | M8: 138397134 | N8: 140528049
A9: BGN.MI | B9: Banca Generali | C9: Italy | D9: FTSE MIB | E9: 115867000 | F9: 116067000 | G9: 116482000 | H9: 115784000 | I9: 115719000 | J9: 115340000 | K9: 115016000 | L9: 114564000 | M9: 114081000 | N9: 114008000
A10: BMED.MI | B10: Banca Mediolanum | C10: Italy | D10: FTSE MIB | E10: 737919428 | F10: 737046913 | G10: 734828052 | H10: 733175893 | I10: 733061303 | J10: 734362421 | K10: 735715806 | L10: 737252214 | M10: 739773622 | N10: 737328000
A11: BAMI.MI | B11: Banco BPM | C11: Italy | D11: FTSE MIB | E11: 488022021 | F11: 817078746 | G11: 1514538059 | H11: 1510954842 | I11: 1511339224 | J11: 1509504749 | K11: 1510823282 | L11: 1508790220 | M11: 1507882573 | N11: 1505001132
A12: BPE.MI | B12: BPER Banca | C12: Italy | D12: FTSE MIB | E12: 710393574 | F12: 710393434 | G12: 710393434 | H12: 710393574 | I12: 732071661 | J12: 679015111 | K12: 1412323581 | L12: 1411912243 | M12: 1415172121 | N12: 1414585000
A13: BZU.MI | B13: Buzzi | C13: Italy | D13: FTSE MIB | E13: 205531808 | F13: 205531808 | G13: 205806808 | H13: 204756665 | I13: 204835151 | J13: 205698335 | K13: 192131838 | L13: 186377503 | M13: 185131873 | N13: 183319589
A14: CPR.MI | B14: Campari Group | C14: Italy | D14: FTSE MIB | E14: 1156034398 | F14: 1157508450 | G14: 1160785339 | H14: 1154903852 | I14: 1144315926 | J14: 1133816568 | K14: 1126588835 | L14: 1126061579 | M14: 1139659102 | N14: 1200346949
A15: CNHI.MI | B15: CNH Industrial | C15: Italy | D15: FTSE MIB | E15: 1361000000 | F15: 1362004209 | G15: 1364000000 | H15: 1357000000 | I15: 1354285714 | J15: 1351000000 | K15: 1354000000 | L15: 1351000000 | M15: 1332000000
A16: DIA.MI | B16: DiaSorin | C16: Italy | D16: FTSE MIB | E16: 54883529 | F16: 54849893 | G16: 54997425 | H16: 55513113 | I16: 54711844 | J16: 54757637 | K16: 57117998 | L16: 57750850 | M16: 55745935 | N16: 55868709
A17: ENEL.MI | B17: Enel | C17: Italy | D17: FTSE MIB | E17: 9403357795 | F17: 9975849408 | G17: 10166679946 | H17: 10163621792 | I17: 10162072640 | J17: 10164612352 | K17: 10162568494 | L17: 10160538038 | M17: 10159406558 | N17: 10156151000
A18: ENI.MI | B18: Eni | C18: Italy | D18: FTSE MIB | E18: 3598190045 | F18: 3601100000 | G18: 3601140133 | H18: 3601140133 | I18: 3592249603 | J18: 3572550000 | K18: 3565974000 | L18: 3483634000 | M18: 3303800000 | N18: 3167006000
A19: EXO.MI | B19: Exor | C19: Italy | D19: FTSE MIB
A20: RACE.MI | B20: Ferrari | C20: Italy | D20: FTSE MIB | G20: 188606000 | H20: 188606000 | I20: 186767000 | J20: 184806000 | K20: 184446000 | L20: 182836000 | M20: 181220000 | N20: 179743000
A21: FBK.MI | B21: FinecoBank | C21: Italy | D21: FTSE MIB | E21: 606101380 | F21: 605659378 | G21: 607158443 | H21: 607575060 | I21: 607720344 | J21: 608966126 | K21: 609692634 | L21: 609932199 | M21: 611547802 | N21: 610829690
A22: HER.MI | B22: Hera Group | C22: Italy | D22: FTSE MIB | E22: 1473737913 | F22: 1471822892 | G22: 1471004233 | H22: 1467966686 | I22: 1472516974 | J22: 1467973723 | K22: 1461238457 | L22: 1454636032 | M22: 1446069736 | N22: 1441926307
A23: INW.MI | B23: Infrastrutture Wireless Italiane | C23: Italy | D23: FTSE MIB | F23: 600000000 | G23: 600000000 | H23: 599966889 | I23: 599777882 | J23: 871314724 | K23: 960115529 | L23: 959914631 | M23: 956019333 | N23: 932386614
A24: IP.MI | B24: Interpump Group | C24: Italy | D24: FTSE MIB | E24: 106854067 | F24: 106196360 | G24: 106973877 | H24: 106766319 | I24: 105452384 | J24: 107104047 | K24: 106664662 | L24: 105593321 | M24: 106927485 | N24: 107104891
A25: ISP.MI | B25: Intesa Sanpaolo | C25: Italy | D25: FTSE MIB | E25: 15832484936 | F25: 15841479283 | G25: 15837253005 | H25: 16772376005 | I25: 17474056000 | J25: 18240491000 | K25: 19377549000 | L25: 19315542000 | M25: 18370426000 | N25: 18017340000
A26: IG.MI | B26: Italgas | C26: Italy | D26: FTSE MIB | G26: 809135502 | H26: 804346153 | I26: 809135502 | J26: 809135502 | K26: 809768354 | L26: 810245718 | M26: 814014814 | N26: 811242309
A27: IVG.MI | B27: Iveco | C27: Italy | D27: FTSE MIB | M27: 269000000 | N27: 267000000
A28: LDO.MI | B28: Leonardo | C28: Italy | D28: FTSE MIB | E28: 574543000 | F28: 574543000 | G28: 574425000 | H28: 574605000 | I28: 574914000 | J28: 574914000 | K28: 575229000 | L28: 575307000 | M28: 575307085 | N28: 575307000
A29: MB.MI | B29: Mediobanca | C29: Italy | D29: FTSE MIB | E29: 847414629 | F29: 849895132 | G29: 854445929 | H29: 877685049 | I29: 871819196 | J29: 860611137 | K29: 862358884 | L29: 838844304 | M29: 840761242 | N29: 826608063
A30: MONC.MI | B30: Moncler | C30: Italy | D30: FTSE MIB | E30: 250086129 | F30: 249268029 | G30: 252060094 | H30: 251723961 | I30: 251723961 | J30: 252674625 | K30: 265570691 | L30: 268974283 | M30: 270106476 | N30: 270522873
A31: NEXI.MI | B31: Nexi | C31: Italy | D31: FTSE MIB | J31: 627778000 | K31: 834754000 | L31: 1310754000 | M31: 1311358000 | N31: 1280958000
A32: PIRC.MI | B32: Pirelli | C32: Italy | D32: FTSE MIB | H32: 1000000000 | I32: 1000000000 | J32: 1000000000 | K32: 1000000000 | L32: 1000000000 | M32: 1000000000 | N32: 1066170213
A33: PST.MI | B33: Poste Italiane | C33: Italy | D33: FTSE MIB | F33: 1306110000 | G33: 1304924242 | H33: 1306110000 | I33: 1300852035 | J33: 1300852035 | K33: 1300877079 | L33: 1298574009 | M33: 1296021578 | N33: 1294805195
A34: PRY.MI | B34: Prysmian Group | C34: Italy | D34: FTSE MIB | E34: 221291692 | F34: 221408573 | G34: 211684000 | H34: 244957000 | I34: 263139000 | J34: 263274000 | K34: 263408000 | L34: 263497000 | M34: 272680412 | N34: 281540000
A35: SPM.MI | B35: Saipem | C35: Italy | D35: FTSE MIB | E35: 139043922 | F35: 175324479 | G35: 210422776 | H35: 209189917 | I35: 209205936 | J35: 208246118 | K35: 197471856 | L35: 940341988 | M35: 1995147895 | N35: 1967618000
A36: SRG.MI | B36: Snam | C36: Italy | D36: FTSE MIB | E36: 3499511044 | F36: 3470733114 | G36: 3422406716 | H36: 3357806084 | I36: 3300593207 | J36: 3272020890 | K36: 3270833636 | L36: 3336596674 | M36: 3353119570 | N36: 3353942449
A37: STLAM.MI | B37: Stellantis | C37: Italy | D37: FTSE MIB | E37: 1510555000 | F37: 1513019000 | G37: 1535988000 | H37: 1548439000 | I37: 1564114000 | J37: 1544002000 | K37: 3059284000 | L37: 3140089000 | M37: 3107725000 | N37: 2949652000
A38: STMMI.MI | B38: STMicroelectronics | C38: Italy | D38: FTSE MIB | E38: 876510959 | F38: 881246870 | G38: 884707764 | H38: 899363170 | I38: 897391304 | J38: 894578477 | K38: 904977376 | L38: 905606885 | M38: 909817559 | N38: 901210072
A39: TEN.MI | B39: Tenaris | C39: Italy | D39: FTSE MIB | E39: 1180537000 | F39: 1180537000 | G39: 1180536830 | H39: 1180537000 | I39: 1180536830 | J39: 1180537000 | K39: 1180537000 | L39: 1180537000 | M39: 1178737751 | N39: 1125107734
A40: TRN.MI | B40: Terna | C40: Italy | D40: FTSE MIB | E40: 2011824324 | F40: 2009841269 | G40: 2012573099 | H40: 2007386363 | I40: 2008753315 | J40: 2008951406 | K40: 1976603267 | L40: 1960586940 | M40: 2005710736 | N40: 2010032179
...

Sheet EPS
A1: Earnings Per Share (€)
A2: EPS = Net Income / Weighted Avg Shares Outstanding. Calculated from source sheets.
A3: Ticker | B3: Company | C3: Country | D3: Index | E3: 2015 | F3: 2016 | G3: 2017 | H3: 2018 | I3: 2019 | J3: 2020 | K3: 2021 | L3: 2022 | M3: 2023 | N3: 2024
A4: ='Net Income'!A4 -> FTSE MIB | B4: ='Net Income'!B4 -> 0 | C4: ='Net Income'!C4 -> 0 | D4: ='Net Income'!D4 -> 0
A5: ='Net Income'!A5 -> A2A.MI | B5: ='Net Income'!B5 -> A2A | C5: ='Net Income'!C5 -> Italy | D5: ='Net Income'!D5 -> FTSE MIB | E5: =IFERROR('Net Income'!E5/'Avg Shares Outstanding'!E5,"") -> 0.023502991 | F5: =IFERROR('Net Income'!F5/'Avg Shares Outstanding'!F5,"") -> 0.07204463 | G5: =IFERROR('Net Income'!G5/'Avg Shares Outstanding'!G5,"") -> 0.094236949 | H5: =IFERROR('Net Income'!H5/'Avg Shares Outstanding'!H5,"") -> 0.11063997 | I5: =IFERROR('Net Income'!I5/'Avg Shares Outstanding'!I5,"") -> 0.12511322 | J5: =IFERROR('Net Income'!J5/'Avg Shares Outstanding'!J5,"") -> 0.11707252 | K5: =IFERROR('Net Income'!K5/'Avg Shares Outstanding'!K5,"") -> 0.16397249 | L5: =IFERROR('Net Income'!L5/'Avg Shares Outstanding'!L5,"") -> 0.13046224 | ... N5: =IFERROR('Net Income'!N5/'Avg Shares Outstanding'!N5,"") -> 0.2758
A6: ='Net Income'!A6 -> AMP.MI | B6: ='Net Income'!B6 -> Amplifon | C6: ='Net Income'!C6 -> Italy | D6: ='Net Income'!D6 -> FTSE MIB | E6: =IFERROR('Net Income'!E6/'Avg Shares Outstanding'!E6,"") -> 0.21465462 | F6: =IFERROR('Net Income'!F6/'Avg Shares Outstanding'!F6,"") -> 0.29007531 | G6: =IFERROR('Net Income'!G6/'Avg Shares Outstanding'!G6,"") -> 0.45905937 | H6: =IFERROR('Net Income'!H6/'Avg Shares Outstanding'!H6,"") -> 0.45706094 | I6: =IFERROR('Net Income'!I6/'Avg Shares Outstanding'!I6,"") -> 0.48978728 | J6: =IFERROR('Net Income'!J6/'Avg Shares Outstanding'!J6,"") -> 0.45131837 | K6: =IFERROR('Net Income'!K6/'Avg Shares Outstanding'!K6,"") -> 0.70181587 | L6: =IFERROR('Net Income'!L6/'Avg Shares Outstanding'!L6,"") -> 0.79569602 | ... N6: =IFERROR('Net Income'!N6/'Avg Shares Outstanding'!N6,"") -> 0.64384035
A7: ='Net Income'!A7 -> G.MI | B7: ='Net Income'!B7 -> Assicurazioni Generali | C7: ='Net Income'!C7 -> Italy | D7: ='Net Income'!D7 -> FTSE MIB | E7: =IFERROR('Net Income'!E7/'Avg Shares Outstanding'!E7,"") -> 1.3042679 | F7: =IFERROR('Net Income'!F7/'Avg Shares Outstanding'!F7,"") -> 1.3352479 | G7: =IFERROR('Net Income'!G7/'Avg Shares Outstanding'!G7,"") -> 1.3518955 | H7: =IFERROR('Net Income'!H7/'Avg Shares Outstanding'!H7,"") -> 1.4765854 | I7: =IFERROR('Net Income'!I7/'Avg Shares Outstanding'!I7,"") -> 1.7028853 | J7: =IFERROR('Net Income'!J7/'Avg Shares Outstanding'!J7,"") -> 1.1112185 | K7: =IFERROR('Net Income'!K7/'Avg Shares Outstanding'!K7,"") -> 1.8097178 | L7: =IFERROR('Net Income'!L7/'Avg Shares Outstanding'!L7,"") -> 1.8545134 | ... N7: =IFERROR('Net Income'!N7/'Avg Shares Outstanding'!N7,"") -> 2.420239
A8: ='Net Income'!A8 -> AZM.MI | B8: ='Net Income'!B8 -> Azimut Holding | C8: ='Net Income'!C8 -> Italy | D8: ='Net Income'!D8 -> FTSE MIB | E8: =IFERROR('Net Income'!E8/'Avg Shares Outstanding'!E8,"") -> 1.7331917 | F8: =IFERROR('Net Income'!F8/'Avg Shares Outstanding'!F8,"") -> 1.2097335 | G8: =IFERROR('Net Income'!G8/'Avg Shares Outstanding'!G8,"") -> 1.6098378 | H8: =IFERROR('Net Income'!H8/'Avg Shares Outstanding'!H8,"") -> 0.88425524 | I8: =IFERROR('Net Income'!I8/'Avg Shares Outstanding'!I8,"") -> 2.6408445 | J8: =IFERROR('Net Income'!J8/'Avg Shares Outstanding'!J8,"") -> 2.7540864 | K8: =IFERROR('Net Income'!K8/'Avg Shares Outstanding'!K8,"") -> 4.3509696 | L8: =IFERROR('Net Income'!L8/'Avg Shares Outstanding'!L8,"") -> 2.9194298 | ... N8: =IFERROR('Net Income'!N8/'Avg Shares Outstanding'!N8,"") -> 4.1
A9: ='Net Income'!A9 -> BGN.MI | B9: ='Net Income'!B9 -> Banca Generali | C9: ='Net Income'!C9 -> Italy | D9: ='Net Income'!D9 -> FTSE MIB | E9: =IFERROR('Net Income'!E9/'Avg Shares Outstanding'!E9,"") -> 1.7568333 | F9: =IFERROR('Net Income'!F9/'Avg Shares Outstanding'!F9,"") -> 1.343138 | G9: =IFERROR('Net Income'!G9/'Avg Shares Outstanding'!G9,"") -> 1.752245 | H9: =IFERROR('Net Income'!H9/'Avg Shares Outstanding'!H9,"") -> 1.5557072 | I9: =IFERROR('Net Income'!I9/'Avg Shares Outstanding'!I9,"") -> 2.3517227 | J9: =IFERROR('Net Income'!J9/'Avg Shares Outstanding'!J9,"") -> 2.383553 | K9: =IFERROR('Net Income'!K9/'Avg Shares Outstanding'!K9,"") -> 2.8092005 | L9: =IFERROR('Net Income'!L9/'Avg Shares Outstanding'!L9,"") -> 1.8595196 | ... N9: =IFERROR('Net Income'!N9/'Avg Shares Outstanding'!N9,"") -> 3.78241
A10: ='Net Income'!A10 -> BMED.MI | B10: ='Net Income'!B10 -> Banca Mediolanum | C10: ='Net Income'!C10 -> Italy | D10: ='Net Income'!D10 -> FTSE MIB | E10: =IFERROR('Net Income'!E10/'Avg Shares Outstanding'!E10,"") -> 0.59439145 | F10: =IFERROR('Net Income'!F10/'Avg Shares Outstanding'!F10,"") -> 0.53392395 | G10: =IFERROR('Net Income'!G10/'Avg Shares Outstanding'!G10,"") -> 0.51711689 | H10: =IFERROR('Net Income'!H10/'Avg Shares Outstanding'!H10,"") -> 0.34877033 | I10: =IFERROR('Net Income'!I10/'Avg Shares Outstanding'!I10,"") -> 0.77132976 | J10: =IFERROR('Net Income'!J10/'Avg Shares Outstanding'!J10,"") -> 0.59161796 | K10: =IFERROR('Net Income'!K10/'Avg Shares Outstanding'!K10,"") -> 0.96919897 | L10: =IFERROR('Net Income'!L10/'Avg Shares Outstanding'!L10,"") -> 0.68745674 | ... N10: =IFERROR('Net Income'!N10/'Avg Shares Outstanding'!N10,"") -> 1.5184952
A11: ='Net Income'!A11 -> BAMI.MI | B11: ='Net Income'!B11 -> Banco BPM | C11: ='Net Income'!C11 -> Italy | D11: ='Net Income'!D11 -> FTSE MIB | E11: =IFERROR('Net Income'!E11/'Avg Shares Outstanding'!E11,"") -> 0.88125736 | F11: =IFERROR('Net Income'!F11/'Avg Shares Outstanding'!F11,"") -> -2.058137 | G11: =IFERROR('Net Income'!G11/'Avg Shares Outstanding'!G11,"") -> 1.7274984 | H11: =IFERROR('Net Income'!H11/'Avg Shares Outstanding'!H11,"") -> -0.039334068 | I11: =IFERROR('Net Income'!I11/'Avg Shares Outstanding'!I11,"") -> 0.52734753 | J11: =IFERROR('Net Income'!J11/'Avg Shares Outstanding'!J11,"") -> 0.013832351 | K11: =IFERROR('Net Income'!K11/'Avg Shares Outstanding'!K11,"") -> 0.37666086 | L11: =IFERROR('Net Income'!L11/'Avg Shares Outstanding'!L11,"") -> 0.45403727 | ... N11: =IFERROR('Net Income'!N11/'Avg Shares Outstanding'!N11,"") -> 1.2760077
A12: ='Net Income'!A12 -> BPE.MI | B12: ='Net Income'!B12 -> BPER Banca | C12: ='Net Income'!C12 -> Italy | D12: ='Net Income'!D12 -> FTSE MIB | E12: =IFERROR('Net Income'!E12/'Avg Shares Outstanding'!E12,"") -> 0.31061796 | F12: =IFERROR('Net Income'!F12/'Avg Shares Outstanding'!F12,"") -> 0.020128283 | G12: =IFERROR('Net Income'!G12/'Avg Shares Outstanding'!G12,"") -> 0.2483666 | H12: =IFERROR('Net Income'!H12/'Avg Shares Outstanding'!H12,"") -> 0.56581734 | I12: =IFERROR('Net Income'!I12/'Avg Shares Outstanding'!I12,"") -> 0.51850525 | J12: =IFERROR('Net Income'!J12/'Avg Shares Outstanding'!J12,"") -> 0.34892449 | K12: =IFERROR('Net Income'!K12/'Avg Shares Outstanding'!K12,"") -> 0.37181493 | L12: =IFERROR('Net Income'!L12/'Avg Shares Outstanding'!L12,"") -> 1.02625 | ... N12: =IFERROR('Net Income'!N12/'Avg Shares Outstanding'!N12,"") -> 0.99156219
A13: ='Net Income'!A13 -> BZU.MI | B13: ='Net Income'!B13 -> Buzzi | C13: ='Net Income'!C13 -> Italy | D13: ='Net Income'!D13 -> FTSE MIB | E13: =IFERROR('Net Income'!E13/'Avg Shares Outstanding'!E13,"") -> 0.60978396 | F13: =IFERROR('Net Income'!F13/'Avg Shares Outstanding'!F13,"") -> 0.70970037 | G13: =IFERROR('Net Income'!G13/'Avg Shares Outstanding'!G13,"") -> 1.9028622 | H13: =IFERROR('Net Income'!H13/'Avg Shares Outstanding'!H13,"") -> 1.8662787 | I13: =IFERROR('Net Income'!I13/'Avg Shares Outstanding'!I13,"") -> 1.882836 | J13: =IFERROR('Net Income'!J13/'Avg Shares Outstanding'!J13,"") -> 2.7236292 | K13: =IFERROR('Net Income'!K13/'Avg Shares Outstanding'!K13,"") -> 2.8204748 | L13: =IFERROR('Net Income'!L13/'Avg Shares Outstanding'!L13,"") -> 2.4615954 | ... N13: =IFERROR('Net Income'!N13/'Avg Shares Outstanding'!N13,"") -> 5.1402908
A14: ='Net Income'!A14 -> CPR.MI | B14: ='Net Income'!B14 -> Campari Group | C14: ='Net Income'!C14 -> Italy | D14: ='Net Income'!D14 -> FTSE MIB | E14: =IFERROR('Net Income'!E14/'Avg Shares Outstanding'!E14,"") -> 0.15172559 | F14: =IFERROR('Net Income'!F14/'Avg Shares Outstanding'!F14,"") -> 0.14367066 | G14: =IFERROR('Net Income'!G14/'Avg Shares Outstanding'!G14,"") -> 0.30703351 | H14: =IFERROR('Net Income'!H14/'Avg Shares Outstanding'!H14,"") -> 0.25655815 | I14: =IFERROR('Net Income'!I14/'Avg Shares Outstanding'!I14,"") -> 0.26950599 | J14: =IFERROR('Net Income'!J14/'Avg Shares Outstanding'!J14,"") -> 0.16572346 | K14: =IFERROR('Net Income'!K14/'Avg Shares Outstanding'!K14,"") -> 0.25279853 | L14: =IFERROR('Net Income'!L14/'Avg Shares Outstanding'!L14,"") -> 0.29572095 | ... N14: =IFERROR('Net Income'!N14/'Avg Shares Outstanding'!N14,"") -> 0.16795144
A15: ='Net Income'!A15 -> CNHI.MI | B15: ='Net Income'!B15 -> CNH Industrial | C15: ='Net Income'!C15 -> Italy | D15: ='Net Income'!D15 -> FTSE MIB | E15: =IFERROR('Net Income'!E15/'Avg Shares Outstanding'!E15,"") -> 0.18589273 | F15: =IFERROR('Net Income'!F15/'Avg Shares Outstanding'!F15,"") -> -0.18502145 | G15: =IFERROR('Net Income'!G15/'Avg Shares Outstanding'!G15,"") -> 0.21627566 | H15: =IFERROR('Net Income'!H15/'Avg Shares Outstanding'!H15,"") -> 0.78703021 | I15: =IFERROR('Net Income'!I15/'Avg Shares Outstanding'!I15,"") -> 1.05 | J15: =IFERROR('Net Income'!J15/'Avg Shares Outstanding'!J15,"") -> -0.33678756 | K15: =IFERROR('Net Income'!K15/'Avg Shares Outstanding'!K15,"") -> 1.2725258 | L15: =IFERROR('Net Income'!L15/'Avg Shares Outstanding'!L15,"") -> 1.5018505 | ... N15: =IFERROR('Net Income'!N15/'Avg Shares Outstanding'!N15,"")
A16: ='Net Income'!A16 -> DIA.MI | B16: ='Net Income'!B16 -> DiaSorin | C16: ='Net Income'!C16 -> Italy | D16: ='Net Income'!D16 -> FTSE MIB | E16: =IFERROR('Net Income'!E16/'Avg Shares Outstanding'!E16,"") -> 1.8296928 | F16: =IFERROR('Net Income'!F16/'Avg Shares Outstanding'!F16,"") -> 2.0489192 | G16: =IFERROR('Net Income'!G16/'Avg Shares Outstanding'!G16,"") -> 2.5433554 | H16: =IFERROR('Net Income'!H16/'Avg Shares Outstanding'!H16,"") -> 2.8484801 | I16: =IFERROR('Net Income'!I16/'Avg Shares Outstanding'!I16,"") -> 3.2120102 | J16: =IFERROR('Net Income'!J16/'Avg Shares Outstanding'!J16,"") -> 4.5266928 | K16: =IFERROR('Net Income'!K16/'Avg Shares Outstanding'!K16,"") -> 5.4443085 | L16: =IFERROR('Net Income'!L16/'Avg Shares Outstanding'!L16,"") -> 4.1714884 | ... N16: =IFERROR('Net Income'!N16/'Avg Shares Outstanding'!N16,"") -> 3.3669115
... A42: ='Net Income'!A42 -> UNI.MI | B42: ='Net Income'!B42 -> Unipol | C42: ='Net Income'!C42 -> Italy | D42: ='Net Income'!D42 -> FTSE MIB | E42: =IFERROR('Net Income'!E42/'Avg Shares Outstanding'!E42,"") -> 0.81771937 | F42: =IFERROR('Net Income'!F42/'Avg Shares Outstanding'!F42,"") -> 0.75490334 | G42: =IFERROR('Net Income'!G42/'Avg Shares Outstanding'!G42,"") -> -0.23806842 | H42: =IFERROR('Net Income'!H42/'Avg Shares Outstanding'!H42,"") -> 1.3073581 | I42: =IFERROR('Net Income'!I42/'Avg Shares Outstanding'!I42,"") -> 1.2604749 | J42: =IFERROR('Net Income'!J42/'Avg Shares Outstanding'!J42,"") -> 0.98785086 | K42: =IFERROR('Net Income'!K42/'Avg Shares Outstanding'!K42,"") -> 0.87501746 | L42: =IFERROR('Net Income'!L42/'Avg Shares Outstanding'!L42,"") -> 0.73395778 | ... N42: =IFERROR('Net Income'!N42/'Avg Shares Outstanding'!N42,"") -> 1.5
A43: ='Net Income'!A43 -> DAX 40 | B43: ='Net Income'!B43 -> 0 | C43: ='Net Income'!C43 -> 0 | D43: ='Net Income'!D43 -> 0
A44: ='Net Income'!A44 -> ADS.DE | B44: ='Net Income'!B44 -> Adidas | C44: ='Net Income'!C44 -> Germany | D44: ='Net Income'!D44 -> DAX 40 | E44: =IFERROR('Net Income'!E44/'Avg Shares Outstanding'!E44,"") -> 3.1458334 | F44: =IFERROR('Net Income'!F44/'Avg Shares Outstanding'!F44,"") -> 5.0802176 | G44: =IFERROR('Net Income'!G44/'Avg Shares Outstanding'!G44,"") -> 5.4201835 | H44: =IFERROR('Net Income'!H44/'Avg Shares Outstanding'!H44,"") -> 8.4358066 | I44: =IFERROR('Net Income'!I44/'Avg Shares Outstanding'!I44,"") -> 9.999691 | J44: =IFERROR('Net Income'!J44/'Avg Shares Outstanding'!J44,"") -> 2.2136146 | K44: =IFERROR('Net Income'!K44/'Avg Shares Outstanding'!K44,"") -> 7.6838702 | L44: =IFERROR('Net Income'!L44/'Avg Shares Outstanding'!L44,"") -> 1.3859815 | ... N44: =IFERROR('Net Income'!N44/'Avg Shares Outstanding'!N44,"") -> 4.2789354
A45: ='Net Income'!A45 -> AIR.DE | B45: ='Net Income'!B45 -> Airbus | C45: ='Net Income'!C45 -> Germany | D45: ='Net Income'!D45 -> DAX 40 | E45: =IFERROR('Net Income'!E45/'Avg Shares Outstanding'!E45,"") -> 3.4316797 | F45: =IFERROR('Net Income'!F45/'Avg Shares Outstanding'!F45,"") -> 1.2858639 | G45: =IFERROR('Net Income'!G45/'Avg Shares Outstanding'!G45,"") -> 3.7129767 | H45: =IFERROR('Net Income'!H45/'Avg Shares Outstanding'!H45,"") -> 3.9397914 | I45: =IFERROR('Net Income'!I45/'Avg Shares Outstanding'!I45,"") -> -1.7051892 | J45: =IFERROR('Net Income'!J45/'Avg Shares Outstanding'!J45,"") -> -1.492636 | K45: =IFERROR('Net Income'!K45/'Avg Shares Outstanding'!K45,"") -> 5.3646506 | L45: =IFERROR('Net Income'!L45/'Avg Shares Outstanding'!L45,"") -> 5.3958897 | ... N45: =IFERROR('Net Income'!N45/'Avg Shares Outstanding'!N45,"") -> 5.3572219
A46: ='Net Income'!A46 -> ALV.DE | B46: ='Net Income'!B46 -> Allianz | C46: ='Net Income'!C46 -> Germany | D46: ='Net Income'!D46 -> DAX 40 | E46: =IFERROR('Net Income'!E46/'Avg Shares Outstanding'!E46,"") -> 14.560908 | F46: =IFERROR('Net Income'!F46/'Avg Shares Outstanding'!F46,"") -> 15.137474 | G46: =IFERROR('Net Income'!G46/'Avg Shares Outstanding'!G46,"") -> 15.238305 | H46: =IFERROR('Net Income'!H46/'Avg Shares Outstanding'!H46,"") -> 17.430225 | I46: =IFERROR('Net Income'!I46/'Avg Shares Outstanding'!I46,"") -> 18.903465 | J46: =IFERROR('Net Income'!J46/'Avg Shares Outstanding'!J46,"") -> 16.484735 | K46: =IFERROR('Net Income'!K46/'Avg Shares Outstanding'!K46,"") -> 16.085697 | L46: =IFERROR('Net Income'!L46/'Avg Shares Outstanding'!L46,"") -> 15.862423 | ... N46: =IFERROR('Net Income'!N46/'Avg Shares Outstanding'!N46,"") -> 25.56492
A47: ='Net Income'!A47 -> BAS.DE | B47: ='Net Income'!B47 -> BASF | C47: ='Net Income'!C47 -> Germany | D47: ='Net Income'!D47 -> DAX 40 | E47: =IFERROR('Net Income'!E47/'Avg Shares Outstanding'!E47,"") -> 4.3408722 | F47: =IFERROR('Net Income'!F47/'Avg Shares Outstanding'!F47,"") -> 4.4159964 | G47: =IFERROR('Net Income'!G47/'Avg Shares Outstanding'!G47,"") -> 6.6174621 | H47: =IFERROR('Net Income'!H47/'Avg Shares Outstanding'!H47,"") -> 5.1247769 | I47: =IFERROR('Net Income'!I47/'Avg Shares Outstanding'!I47,"") -> 2.7719741 | J47: =IFERROR('Net Income'!J47/'Avg Shares Outstanding'!J47,"") -> -1.6015608 | K47: =IFERROR('Net Income'!K47/'Avg Shares Outstanding'!K47,"") -> 6.0132023 | L47: =IFERROR('Net Income'!L47/'Avg Shares Outstanding'!L47,"") -> -0.43359941 | ... N47: =IFERROR('Net Income'!N47/'Avg Shares Outstanding'!N47,"") -> 1.4500007
A48: ='Net Income'!A48 -> BMW.DE | B48: ='Net Income'!B48 -> BMW | C48: ='Net Income'!C48 -> Germany | D48: ='Net Income'!D48 -> DAX 40 | E48: =IFERROR('Net Income'!E48/'Avg Shares Outstanding'!E48,"") -> 9.701526 | F48: =IFERROR('Net Income'!F48/'Avg Shares Outstanding'!F48,"") -> 10.449075 | G48: =IFERROR('Net Income'!G48/'Avg Shares Outstanding'!G48,"") -> 13.118057 | H48: =IFERROR('Net Income'!H48/'Avg Shares Outstanding'!H48,"") -> 10.822679 | I48: =IFERROR('Net Income'!I48/'Avg Shares Outstanding'!I48,"") -> 7.468265 | J48: =IFERROR('Net Income'!J48/'Avg Shares Outstanding'!J48,"") -> 5.7243721 | K48: =IFERROR('Net Income'!K48/'Avg Shares Outstanding'!K48,"") -> 18.764008 | L48: =IFERROR('Net Income'!L48/'Avg Shares Outstanding'!L48,"") -> 27.303363 | ... N48: =IFERROR('Net Income'!N48/'Avg Shares Outstanding'!N48,"") -> 12.776046
A49: ='Net Income'!A49 -> BAYN.DE | B49: ='Net Income'!B49 -> Bayer | C49: ='Net Income'!C49 -> Germany | D49: ='Net Income'!D49 -> DAX 40 | E49: =IFERROR('Net Income'!E49/'Avg Shares Outstanding'!E49,"") -> 4.9700839 | F49: =IFERROR('Net Income'!F49/'Avg Shares Outstanding'!F49,"") -> 5.4426243 | G49: =IFERROR('Net Income'!G49/'Avg Shares Outstanding'!G49,"") -> 8.4118022 | H49: =IFERROR('Net Income'!H49/'Avg Shares Outstanding'!H49,"") -> 1.8017348 | I49: =IFERROR('Net Income'!I49/'Avg Shares Outstanding'!I49,"") -> 2.4753232 | J49: =IFERROR('Net Income'!J49/'Avg Shares Outstanding'!J49,"") -> -15.839458 | K49: =IFERROR('Net Income'!K49/'Avg Shares Outstanding'!K49,"") -> 1.0178946 | L49: =IFERROR('Net Income'!L49/'Avg Shares Outstanding'!L49,"") -> 4.2242625 | ... N49: =IFERROR('Net Income'!N49/'Avg Shares Outstanding'!N49,"") -> -2.597667
A50: ='Net Income'!A50 -> BEI.DE | B50: ='Net Income'!B50 -> Beiersdorf | C50: ='Net Income'!C50 -> Germany | D50: ='Net Income'!D50 -> DAX 40 | E50: =IFERROR('Net Income'!E50/'Avg Shares Outstanding'!E50,"") -> 2.9098093 | F50: =IFERROR('Net Income'!F50/'Avg Shares Outstanding'!F50,"") -> 3.1258406 | G50: =IFERROR('Net Income'!G50/'Avg Shares Outstanding'!G50,"") -> 2.962715 | H50: =IFERROR('Net Income'!H50/'Avg Shares Outstanding'!H50,"") -> 3.2096079 | I50: =IFERROR('Net Income'!I50/'Avg Shares Outstanding'!I50,"") -> 3.1655199 | J50: =IFERROR('Net Income'!J50/'Avg Shares Outstanding'!J50,"") -> 2.4689291 | K50: =IFERROR('Net Income'!K50/'Avg Shares Outstanding'!K50,"") -> 2.8128157 | L50: =IFERROR('Net Income'!L50/'Avg Shares Outstanding'!L50,"") -> 3.3286455 | ... N50: =IFERROR('Net Income'!N50/'Avg Shares Outstanding'!N50,"") -> 4.0540644
A51: ='Net Income'!A51 -> BNR.DE | B51: ='Net Income'!B51 -> Brenntag | C51: ='Net Income'!C51 -> Germany | D51: ='Net Income'!D51 -> DAX 40 | E51: =IFERROR('Net Income'!E51/'Avg Shares Outstanding'!E51,"") -> 2.3624595 | F51: =IFERROR('Net Income'!F51/'Avg Shares Outstanding'!F51,"") -> 2.3320388 | G51: =IFERROR('Net Income'!G51/'Avg Shares Outstanding'!G51,"") -> 2.3352751 | H51: =IFERROR('Net Income'!H51/'Avg Shares Outstanding'!H51,"") -> 2.9831715 | I51: =IFERROR('Net Income'!I51/'Avg Shares Outstanding'!I51,"") -> 3.020712 | J51: =IFERROR('Net Income'!J51/'Avg Shares Outstanding'!J51,"") -> 3.0194175 | K51: =IFERROR('Net Income'!K51/'Avg Shares Outstanding'!K51,"") -> 2.9016181 | L51: =IFERROR('Net Income'!L51/'Avg Shares Outstanding'!L51,"") -> 5.7398058 | ... N51: =IFERROR('Net Income'!N51/'Avg Shares Outstanding'!N51,"") -> 3.7055978
A52: ='Net Income'!A52 -> CBK.DE | B52: ='Net Income'!B52 -> Commerzbank | C52: ='Net Income'!C52 -> Germany | D52: ='Net Income'!D52 -> DAX 40 | E52: =IFERROR('Net Income'!E52/'Avg Shares Outstanding'!E52,"") -> 0.87872524 | F52: =IFERROR('Net Income'!F52/'Avg Shares Outstanding'!F52,"") -> 0.22277981 | G52: =IFERROR('Net Income'!G52/'Avg Shares Outstanding'!G52,"") -> 0.12456506 | H52: =IFERROR('Net Income'!H52/'Avg Shares Outstanding'!H52,"") -> 0.69069727 | I52: =IFERROR('Net Income'!I52/'Avg Shares Outstanding'!I52,"") -> 0.51423011 | J52: =IFERROR('Net Income'!J52/'Avg Shares Outstanding'!J52,"") -> -2.3076475 | K52: =IFERROR('Net Income'!K52/'Avg Shares Outstanding'!K52,"") -> 0.3433524 | L52: =IFERROR('Net Income'!L52/'Avg Shares Outstanding'!L52,"") -> 1.1458388 | ... N52: =IFERROR('Net Income'!N52/'Avg Shares Outstanding'!N52,"") -> 2.254293
A53: ='Net Income'!A53 -> CON.DE | B53: ='Net Income'!B53 -> Continental | C53: ='Net Income'!C53 -> Germany | D53: ='Net Income'!D53 -> DAX 40 | E53: =IFERROR('Net Income'!E53/'Avg Shares Outstanding'!E53,"") -> 13.637 | F53: =IFERROR('Net Income'!F53/'Avg Shares Outstanding'!F53,"") -> 14.0125 | G53: =IFERROR('Net Income'!G53/'Avg Shares Outstanding'!G53,"") -> 14.923 | H53: =IFERROR('Net Income'!H53/'Avg Shares Outstanding'!H53,"") -> 14.4865 | I53: =IFERROR('Net Income'!I53/'Avg Shares Outstanding'!I53,"") -> -5.855 | J53: =IFERROR('Net Income'!J53/'Avg Shares Outstanding'!J53,"") -> -4.594 | K53: =IFERROR('Net Income'!K53/'Avg Shares Outstanding'!K53,"") -> 7.176 | L53: =IFERROR('Net Income'!L53/'Avg Shares Outstanding'!L53,"") -> 0.561 | ... N53: =IFERROR('Net Income'!N53/'Avg Shares Outstanding'!N53,"") -> 5.84
A54: ='Net Income'!A54 -> 1COV.DE | B54: ='Net Income'!B54 -> Covestro | C54: ='Net Income'!C54 -> Germany | D54: ='Net Income'!D54 -> DAX 40 | E54: =IFERROR('Net Income'!E54/'Avg Shares Outstanding'!E54,"") | F54: =IFERROR('Net Income'!F54/'Avg Shares Outstanding'!F54,"") -> 3.9259259 | G54: =IFERROR('Net Income'!G54/'Avg Shares Outstanding'!G54,"") -> 9.9260651 | H54: =IFERROR('Net Income'!H54/'Avg Shares Outstanding'!H54,"") -> 9.4569233 | I54: =IFERROR('Net Income'!I54/'Avg Shares Outstanding'!I54,"") -> 3.0208715 | J54: =IFERROR('Net Income'!J54/'Avg Shares Outstanding'!J54,"") -> 2.4822591 | K54: =IFERROR('Net Income'!K54/'Avg Shares Outstanding'!K54,"") -> 8.3658876 | L54: =IFERROR('Net Income'!L54/'Avg Shares Outstanding'!L54,"") -> -1.4717171 | ... N54: =IFERROR('Net Income'!N54/'Avg Shares Outstanding'!N54,"") -> -1.4093437
A55: ='Net Income'!A55 -> DTG.DE | B55: ='Net Income'!B55 -> Daimler Truck | C55: ='Net Income'!C55 -> Germany | D55: ='Net Income'!D55 -> DAX 40 | E55: =IFERROR('Net Income'!E55/'Avg Shares Outstanding'!E55,"") | F55: =IFERROR('Net Income'!F55/'Avg Shares Outstanding'!F55,"") | G55: =IFERROR('Net Income'!G55/'Avg Shares Outstanding'!G55,"") | H55: =IFERROR('Net Income'!H55/'Avg Shares Outstanding'!H55,"") | I55: =IFERROR('Net Income'!I55/'Avg Shares Outstanding'!I55,"") | J55: =IFERROR('Net Income'!J55/'Avg Shares Outstanding'!J55,"") | K55: =IFERROR('Net Income'!K55/'Avg Shares Outstanding'!K55,"") | L55: =IFERROR('Net Income'!L55/'Avg Shares Outstanding'!L55,"") -> 3.2383424 | ... N55: =IFERROR('Net Income'!N55/'Avg Shares Outstanding'!N55,"") -> 3.6432161
... A83: ='Net Income'!A83 -> ZAL.DE | B83: ='Net Income'!B83 -> Zalando | C83: ='Net Income'!C83 -> Germany | D83: ='Net Income'!D83 -> DAX 40 | E83: =IFERROR('Net Income'!E83/'Avg Shares Outstanding'!E83,"") -> 0.49350122 | F83: =IFERROR('Net Income'!F83/'Avg Shares Outstanding'!F83,"") -> 0.48745955 | G83: =IFERROR('Net Income'!G83/'Avg Shares Outstanding'!G83,"") -> 0.41690255 | H83: =IFERROR('Net Income'!H83/'Avg Shares Outstanding'!H83,"") -> 0.20784472 | I83: =IFERROR('Net Income'!I83/'Avg Shares Outstanding'!I83,"") -> 0.40266559 | J83: =IFERROR('Net Income'!J83/'Avg Shares Outstanding'!J83,"") -> 0.90259481 | K83: =IFERROR('Net Income'!K83/'Avg Shares Outstanding'!K83,"") -> 0.91032609 | L83: =IFERROR('Net Income'!L83/'Avg Shares Outstanding'!L83,"") -> 0.065141528 | ... N83: =IFERROR('Net Income'!N83/'Avg Shares Outstanding'!N83,"") -> 0.96912389
A84: ='Net Income'!A84 -> CAC 40 | B84: ='Net Income'!B84 -> 0 | C84: ='Net Income'!C84 -> 0 | D84: ='Net Income'!D84 -> 0
A85: ='Net Income'!A85 -> MC.PA | B85: ='Net Income'!B85 -> LVMH | C85: ='Net Income'!C85 -> France | D85: ='Net Income'!D85 -> CAC 40 | E85: =IFERROR('Net Income'!E85/'Avg Shares Outstanding'!E85,"") -> 7.1119269 | F85: =IFERROR('Net Income'!F85/'Avg Shares Outstanding'!F85,"") -> 8.0849275 | G85: =IFERROR('Net Income'!G85/'Avg Shares Outstanding'!G85,"") -> 10.678472 | H85: =IFERROR('Net Income'!H85/'Avg Shares Outstanding'!H85,"") -> 12.636592 | I85: =IFERROR('Net Income'!I85/'Avg Shares Outstanding'!I85,"") -> 14.250261 | J85: =IFERROR('Net Income'!J85/'Avg Shares Outstanding'!J85,"") -> 9.3353057 | K85: =IFERROR('Net Income'!K85/'Avg Shares Outstanding'!K85,"") -> 23.898606 | L85: =IFERROR('Net Income'!L85/'Avg Shares Outstanding'!L85,"") -> 28.049033 | ... N85: =IFERROR('Net Income'!N85/'Avg Shares Outstanding'!N85,"") -> 25.129502
A86: ='Net Income'!A86 -> SU.PA | B86: ='Net Income'!B86 -> Schneider Electric | C86: ='Net Income'!C86 -> France | D86: ='Net Income'!D86 -> CAC 40 | E86: =IFERROR('Net Income'!E86/'Avg Shares Outstanding'!E86,"") -> 2.4756046 | F86: =IFERROR('Net Income'!F86/'Avg Shares Outstanding'!F86,"") -> 3.1181957 | G86: =IFERROR('Net Income'!G86/'Avg Shares Outstanding'!G86,"") -> 3.854905 | H86: =IFERROR('Net Income'!H86/'Avg Shares Outstanding'!H86,"") -> 4.2129508 | I86: =IFERROR('Net Income'!I86/'Avg Shares Outstanding'!I86,"") -> 4.3787779 | J86: =IFERROR('Net Income'!J86/'Avg Shares Outstanding'!J86,"") -> 3.8391598 | K86: =IFERROR('Net Income'!K86/'Avg Shares Outstanding'!K86,"") -> 5.758116 | L86: =IFERROR('Net Income'!L86/'Avg Shares Outstanding'!L86,"") -> 6.2297426 | ... N86: =IFERROR('Net Income'!N86/'Avg Shares Outstanding'!N86,"") -> 7.6134799
A87: ='Net Income'!A87 -> AIR.PA | B87: ='Net Income'!B87 -> Airbus | C87: ='Net Income'!C87 -> France | D87: ='Net Income'!D87 -> CAC 40 | E87: =IFERROR('Net Income'!E87/'Avg Shares Outstanding'!E87,"") -> 3.4316797 | F87: =IFERROR('Net Income'!F87/'Avg Shares Outstanding'!F87,"") -> 1.2858639 | G87: =IFERROR('Net Income'!G87/'Avg Shares Outstanding'!G87,"") -> 3.0512837 | H87: =IFERROR('Net Income'!H87/'Avg Shares Outstanding'!H87,"") -> 3.9397914 | I87: =IFERROR('Net Income'!I87/'Avg Shares Outstanding'!I87,"") -> -1.7051892 | J87: =IFERROR('Net Income'!J87/'Avg Shares Outstanding'!J87,"") -> -1.492636 | K87: =IFERROR('Net Income'!K87/'Avg Shares Outstanding'!K87,"") -> 5.3646506 | L87: =IFERROR('Net Income'!L87/'Avg Shares Outstanding'!L87,"") -> 5.3958897 | ... N87: =IFERROR('Net Income'!N87/'Avg Shares Outstanding'!N87,"") -> 5.3572219
A88: ='Net Income'!A88 -> TTE.PA | B88: ='Net Income'!B88 -> TotalEnergies | C88: ='Net Income'!C88 -> France | D88: ='Net Income'!D88 -> CAC 40 | E88: =IFERROR('Net Income'!E88/'Avg Shares Outstanding'!E88,"") -> 2.2165211 | F88: =IFERROR('Net Income'!F88/'Avg Shares Outstanding'!F88,"") -> 2.6042563 | G88: =IFERROR('Net Income'!G88/'Avg Shares Outstanding'!G88,"") -> 3.4777141 | H88: =IFERROR('Net Income'!H88/'Avg Shares Outstanding'!H88,"") -> 4.3897178 | I88: =IFERROR('Net Income'!I88/'Avg Shares Outstanding'!I88,"") -> 4.3307601 | J88: =IFERROR('Net Income'!J88/'Avg Shares Outstanding'!J88,"") -> -2.783215 | K88: =IFERROR('Net Income'!K88/'Avg Shares Outstanding'!K88,"") -> 6.0925219 | L88: =IFERROR('Net Income'!L88/'Avg Shares Outstanding'!L88,"") -> 8.0345796 | ... N88: =IFERROR('Net Income'!N88/'Avg Shares Outstanding'!N88,"") -> 6.8572015
A89: ='Net Income'!A89 -> SAN.PA | B89: ='Net Income'!B89 -> Sanofi | C89: ='Net Income'!C89 -> France | D89: ='Net Income'!D89 -> CAC 40 | E89: =IFERROR('Net Income'!E89/'Avg Shares Outstanding'!E89,"") -> 3.2461075 | F89: =IFERROR('Net Income'!F89/'Avg Shares Outstanding'!F89,"") -> 3.6600342 | G89: =IFERROR('Net Income'!G89/'Avg Shares Outstanding'!G89,"") -> 3.0755685 | H89: =IFERROR('Net Income'!H89/'Avg Shares Outstanding'!H89,"") -> 3.4528105 | I89: =IFERROR('Net Income'!I89/'Avg Shares Outstanding'!I89,"") -> 2.2449796 | J89: =IFERROR('Net Income'!J89/'Avg Shares Outstanding'!J89,"") -> 9.806956 | K89: =IFERROR('Net Income'!K89/'Avg Shares Outstanding'!K89,"") -> 4.9684631 | L89: =IFERROR('Net Income'!L89/'Avg Shares Outstanding'!L89,"") -> 6.6866363 | ... N89: =IFERROR('Net Income'!N89/'Avg Shares Outstanding'!N89,"") -> 4.4430238
A90: ='Net Income'!A90 -> SAF.PA | B90: ='Net Income'!B90 -> Safran | C90: ='Net Income'!C90 -> France | D90: ='Net Income'!D90 -> CAC 40 | E90: =IFERROR('Net Income'!E90/'Avg Shares Outstanding'!E90,"") -> -1.0806186 | F90: =IFERROR('Net Income'!F90/'Avg Shares Outstanding'!F90,"") -> 4.5829567 | G90: =IFERROR('Net Income'!G90/'Avg Shares Outstanding'!G90,"") -> 11.09104 | H90: =IFERROR('Net Income'!H90/'Avg Shares Outstanding'!H90,"") -> 2.9774074 | I90: =IFERROR('Net Income'!I90/'Avg Shares Outstanding'!I90,"") -> 5.694361 | J90: =IFERROR('Net Income'!J90/'Avg Shares Outstanding'!J90,"") -> 0.82622178 | K90: =IFERROR('Net Income'!K90/'Avg Shares Outstanding'!K90,"") -> 0.10078509 | L90: =IFERROR('Net Income'!L90/'Avg Shares Outstanding'!L90,"") -> -5.7630923 | ... N90: =IFERROR('Net Income'!N90/'Avg Shares Outstanding'!N90,"") -> -1.6027893
A91: ='Net Income'!A91 -> AI.PA | B91: ='Net Income'!B91 -> Air Liquide | C91: ='Net Income'!C91 -> France | D91: ='Net Income'!D91 -> CAC 40 | E91: =IFERROR('Net Income'!E91/'Avg Shares Outstanding'!E91,"") -> 3.4084328 | F91: =IFERROR('Net Income'!F91/'Avg Shares Outstanding'!F91,"") -> 3.4912547 | G91: =IFERROR('Net Income'!G91/'Avg Shares Outstanding'!G91,"") -> 3.8756018 | H91: =IFERROR('Net Income'!H91/'Avg Shares Outstanding'!H91,"") -> 3.7117502 | I91: =IFERROR('Net Income'!I91/'Avg Shares Outstanding'!I91,"") -> 3.9312828 | J91: =IFERROR('Net Income'!J91/'Avg Shares Outstanding'!J91,"") -> 4.2673129 | K91: =IFERROR('Net Income'!K91/'Avg Shares Outstanding'!K91,"") -> 4.4896991 | L91: =IFERROR('Net Income'!L91/'Avg Shares Outstanding'!L91,"") -> 4.8039625 | ... N91: =IFERROR('Net Income'!N91/'Avg Shares Outstanding'!N91,"") -> 5.735201
A92: ='Net Income'!A92 -> OR.PA | B92: ='Net Income'!B92 -> L'Oreal | C92: ='Net Income'!C92 -> France | D92: ='Net Income'!D92 -> CAC 40 | E92: =IFERROR('Net Income'!E92/'Avg Shares Outstanding'!E92,"") -> 5.9161975 | F92: =IFERROR('Net Income'!F92/'Avg Shares Outstanding'!F92,"") -> 5.5541017 | G92: =IFERROR('Net Income'!G92/'Avg Shares Outstanding'!G92,"") -> 6.4041211 | H92: =IFERROR('Net Income'!H92/'Avg Shares Outstanding'!H92,"") -> 6.9610039 | I92: =IFERROR('Net Income'!I92/'Avg Shares Outstanding'!I92,"") -> 6.6995424 | J92: =IFERROR('Net Income'!J92/'Avg Shares Outstanding'!J92,"") -> 6.3734423 | K92: =IFERROR('Net Income'!K92/'Avg Shares Outstanding'!K92,"") -> 8.2444301 | L92: =IFERROR('Net Income'!L92/'Avg Shares Outstanding'!L92,"") -> 10.648655 | ... N92: =IFERROR('Net Income'!N92/'Avg Shares Outstanding'!N92,"") -> 11.990469
...

Sheet Stock Prices
A1: Year-End Closing Stock Prices (€)
A2: Values to be filled manually. Blue cells = data input fields.
D3: Last Trading Day | E3: 12/30/2014 | F3: 12/30/2015 | G3: 12/30/2016 | H3: 12/29/2017 | I3: 12/28/2018 | J3: 12/30/2019 | K3: 12/30/2020 | L3: 12/30/2021 | M3: 12/30/2022 | N3: 12/29/2023 | O3: 12/30/2024
A4: Ticker | B4: Company | C4: Country | D4: Index | E4: 2014 | F4: 2015 | G4: 2016 | H4: 2017 | I4: 2018 | J4: 2019 | K4: 2020 | L4: 2021 | M4: 2022 | N4: 2023 | O4: 2024
A5: FTSE MIB
A6: A2A.MI | B6: A2A | C6: Italy | D6: FTSE MIB | E6: 0.8375 | F6: 1.25 | G6: 1.23 | H6: 1.54 | I6: 1.57 | J6: 1.67 | K6: 1.3 | L6: 1.72 | M6: 1.25 | N6: 1.86 | O6: 2.15
A7: AMP.MI | B7: Amplifon | C7: Italy | D7: FTSE MIB | E7: 4.9 | F7: 8 | G7: 9.05 | H7: 12.84 | I7: 14.05 | J7: 25.64 | K7: 34.04 | L7: 47.45 | M7: 27.82 | N7: 31.34 | O7: 24.85
A8: G.MI | B8: Assicurazioni Generali | C8: Italy | D8: FTSE MIB | E8: 17 | F8: 16.92 | G8: 14.12 | H8: 15.2 | I8: 14.6 | J8: 18.4 | K8: 14.26 | L8: 18.63 | M8: 16.61 | N8: 19.11 | O8: 27.27
A9: AZM.MI | B9: Azimut Holding | C9: Italy | D9: FTSE MIB | E9: 16.55 | F9: 21.17 | G9: 14.56 | H9: 14.66 | I9: 9.23 | J9: 20.98 | K9: 17.52 | L9: 24.33 | M9: 20.63 | N9: 23.3 | O9: 23.99
A10: BGN.MI | B10: Banca Generali | C10: Italy | D10: FTSE MIB | E10: 23.05 | F10: 29.18 | G10: 22.66 | H10: 27.74 | I10: 18.13 | J10: 28.96 | K10: 27.24 | L10: 38.75 | M10: 32.06 | N10: 33.64 | O10: 44.86
A11: BMED.MI | B11: Banca Mediolanum | C11: Italy | D11: FTSE MIB | E11: 5.29 | F11: 7.31 | G11: 6.83 | H11: 7.22 | I11: 5.09 | J11: 8.86 | K11: 7.1 | L11: 8.68 | M11: 7.8 | N11: 8.53 | O11: 11.49
A12: BAMI.MI | B12: Banco BPM | C12: Italy | D12: FTSE MIB | E12: 7.46 | F12: 9.5 | G12: 2.29 | H12: 2.62 | I12: 1.97 | J12: 2.03 | K12: 1.81 | L12: 2.64 | M12: 3.33 | N12: 4.78 | O12: 7.81
A13: BPE.MI | B13: BPER Banca | C13: Italy | D13: FTSE MIB | E13: 3.7 | F13: 4.77 | G13: 3.43 | H13: 2.85 | I13: 2.28 | J13: 3.03 | K13: 1.49 | L13: 1.82 | M13: 1.92 | N13: 3.03 | O13: 6.13
A14: BZU.MI | B14: Buzzi | C14: Italy | D14: FTSE MIB | E14: 10.51 | F14: 16.6 | G14: 22.51 | H14: 22.5 | I14: 15.025 | J14: 22.450001 | K14: 19.5 | L14: 18.975 | M14: 18 | N14: 27.54 | O14: 35.58
A15: CPR.MI | B15: Campari Group | C15: Italy | D15: FTSE MIB | E15: 2.58 | F15: 4 | G15: 4.64 | H15: 6.45 | I15: 7.39 | J15: 8.14 | K15: 9.34 | L15: 12.86 | M15: 9.48 | N15: 10.22 | O15: 6.02
A16: CNHI.MI | B16: CNH Industrial | C16: Italy | D16: FTSE MIB | E16: 6.7 | F16: 6.34 | G16: 8.27 | H16: 11.17 | I16: 7.85 | J16: 9.79 | K16: 10.33 | L16: 14.82 | M16: 14.97 | N16: 11.08 | O16: 0
A17: DIA.MI | B17: DiaSorin | C17: Italy | D17: FTSE MIB | E17: 33.33 | F17: 48.45 | G17: 56.25 | H17: 74 | I17: 70.7 | J17: 115.4 | K17: 170.1 | L17: 167.45 | M17: 130.4 | N17: 93.24 | O17: 99.56
... A43: UNI.MI | B43: Unipol | C43: Italy | D43: FTSE MIB | E43: 4.12 | F43: 4.764 | G43: 3.424 | H43: 3.91 | I43: 3.518 | J43: 5.112 | K43: 3.91 | L43: 4.779 | M43: 4.558 | N43: 5.16 | O43: 12.03
A44: DAX 40
A45: ADS.DE | B45: Adidas | C45: Germany | D45: DAX 40 | E45: 57.62 | F45: 89.91 | G45: 150.15 | H45: 167.15 | I45: 182.4 | J45: 289.8 | K45: 297.9 | L45: 253.2 | M45: 127.46 | N45: 184.16 | O45: 236.8
A46: AIR.DE | B46: Airbus | C46: Germany | D46: DAX 40 | E46: 41.1 | F46: 62.75 | G46: 62.71 | H46: 83.67 | I46: 83.51 | J46: 132.14 | K46: 91.32 | L46: 111.72 | M46: 111.38 | N46: 140.08 | O46: 154.46
A47: ALV.DE | B47: Allianz | C47: Germany | D47: DAX 40 | E47: 137.35 | F47: 163.55 | G47: 157 | H47: 191.5 | I47: 175.14 | J47: 218.4 | K47: 200.7 | L47: 207.65 | M47: 200.9 | N47: 241.95 | O47: 295.9
A48: BAS.DE | B48: BASF | C48: Germany | D48: DAX 40 | E48: 69.88 | F48: 70.72 | G48: 88.31 | H48: 91.74 | I48: 60.4 | J48: 67.35 | K48: 64.72 | L48: 61.78 | M48: 46.39 | N48: 48.78 | O48: 42.46
A49: BMW.DE | B49: BMW | C49: Germany | D49: DAX 40 | E49: 89.77 | F49: 97.63 | G49: 88.75 | H49: 86.83 | I49: 70.7 | J49: 73.14 | K49: 72.23 | L49: 88.49 | M49: 83.38 | N49: 100.78 | O49: 78.98
A50: BAYN.DE | B50: Bayer | C50: Germany | D50: DAX 40 | E50: 111.2 | F50: 113.96 | G50: 97.55 | H50: 102.35 | I50: 60.56 | J50: 72.81 | K50: 48.15 | L50: 47 | M50: 48.33 | N50: 33.63 | O50: 19.31
A51: BEI.DE | B51: Beiersdorf | C51: Germany | D51: DAX 40 | E51: 67.42 | F51: 84.16 | G51: 80.6 | H51: 97.9 | I51: 91.16 | J51: 106.65 | K51: 94.44 | L51: 90.38 | M51: 107.2 | N51: 135.7 | O51: 124
A52: BNR.DE | B52: Brenntag | C52: Germany | D52: DAX 40 | E52: 46.51 | F52: 48.28 | G52: 52.8 | H52: 52.77 | I52: 37.7 | J52: 48.48 | K52: 63.34 | L52: 79.58 | M52: 59.72 | N52: 83.22 | O52: 57.88
A53: CBK.DE | B53: Commerzbank | C53: Germany | D53: DAX 40 | E53: 10.98 | F53: 9.57 | G53: 7.25 | H53: 12.51 | I53: 5.78 | J53: 5.52 | K53: 5.27 | L53: 6.69 | M53: 8.84 | N53: 10.76 | O53: 15.73
A54: CON.DE | B54: Continental | C54: Germany | D54: DAX 40 | E54: 156.11 | F54: 199.69 | G54: 163.36 | H54: 200.13 | I54: 107.38 | J54: 102.5 | K54: 107.82 | L54: 93.11 | M54: 55.98 | N54: 76.92 | O54: 64.82
A55: 1COV.DE | B55: Covestro | C55: Germany | D55: DAX 40 | E55: 0 | F55: 33.63 | G55: 65.18 | H55: 86.03 | I55: 43.18 | J55: 41.45 | K55: 50.48 | L55: 54.2 | M55: 36.55 | N55: 52.68 | O55: 56.16
A56: DTG.DE | B56: Daimler Truck | C56: Germany | D56: DAX 40 | E56: 0 | F56: 0 | G56: 0 | H56: 0 | I56: 0 | J56: 0 | K56: 0 | L56: 32.29 | M56: 28.95 | N56: 34.02 | O56: 36.85
... A84: ZAL.DE | B84: Zalando | C84: Germany | D84: DAX 40 | E84: 25.5 | F84: 36.4 | G84: 36.29 | H84: 44.12 | I84: 22.44 | J84: 45.18 | K84: 91.06 | L84: 71.14 | M84: 33.11 | N84: 21.45 | O84: 32.39
A85: CAC 40
A86: MC.PA | B86: LVMH | C86: France | D86: CAC 40 | E86: 131.15 | F86: 147.15 | G86: 181.4 | H86: 245.4 | I86: 252.75 | J86: 414.6 | K86: 513.1 | L86: 730 | M86: 679.9 | N86: 733.6 | O86: 629.3
A87: SU.PA | B87: Schneider Electric | C87: France | D87: CAC 40 | E87: 59.65 | F87: 53.68 | G87: 66.11 | H87: 70.86 | I87: 59.32 | J87: 91.54 | K87: 120.85 | L87: 172.84 | M87: 130.72 | N87: 181.78 | O87: 239.4
A88: AIR.PA | B88: Airbus | C88: France | D88: CAC 40 | E88: 40.94 | F88: 62.58 | G88: 62.84 | H88: 83 | I88: 83.76 | J88: 130 | K88: 91.25 | L88: 112.68 | M88: 111.02 | N88: 139.78 | O88: 154.38
A89: TTE.PA | B89: TotalEnergies | C89: France | D89: CAC 40 | E89: 42.54 | F89: 41.56 | G89: 48.72 | H89: 46.04 | I89: 46.08 | J89: 49.19 | K89: 35.59 | L89: 44.9 | M89: 58.65 | N89: 61.6 | O89: 52.6
A90: SAN.PA | B90: Sanofi | C90: France | D90: CAC 40 | E90: 75 | F90: 79.71 | G90: 76.9 | H90: 71.85 | I90: 75.22 | J90: 89.75 | K90: 78.86 | L90: 89.13 | M90: 89.84 | N90: 89.76 | O90: 93.14
A91: SAF.PA | B91: Safran | C91: France | D91: CAC 40 | E91: 50.42 | F91: 63.75 | G91: 68.42 | H91: 85.91 | I91: 103.1 | J91: 137.1 | K91: 119 | L91: 107.08 | M91: 116.92 | N91: 159.46 | O91: 210.4
A92: AI.PA | B92: Air Liquide | C92: France | D92: CAC 40 | E92: 67.51 | F92: 69.49 | G92: 71.79 | H92: 78.52 | I92: 79.41 | J92: 103.55 | K92: 111.24 | L92: 126.35 | M92: 120.05 | N92: 159.69 | O92: 154.62
...

Sheet Stock Price Return
A1: Annual Stock Price Return (%)
A2: Values to be filled manually. Blue cells = data input fields.
A3: Ticker | B3: Company | C3: Country | D3: Index | E3: 2015 | F3: 2016 | G3: 2017 | H3: 2018 | I3: 2019 | J3: 2020 | K3: 2021 | L3: 2022 | M3: 2023 | N3: 2024
A4: FTSE MIB
A5: A2A.MI | B5: A2A | C5: Italy | D5: FTSE MIB | E5: =('Stock Prices'!F6-'Stock Prices'!E6)/'Stock Prices'!E6 -> 0.49253731 | F5: =('Stock Prices'!G6-'Stock Prices'!F6)/'Stock Prices'!F6 -> -0.016 | G5: =('Stock Prices'!H6-'Stock Prices'!G6)/'Stock Prices'!G6 -> 0.25203252 | H5: =('Stock Prices'!I6-'Stock Prices'!H6)/'Stock Prices'!H6 -> 0.019480519 | I5: =('Stock Prices'!J6-'Stock Prices'!I6)/'Stock Prices'!I6 -> 0.063694268 | J5: =('Stock Prices'!K6-'Stock Prices'!J6)/'Stock Prices'!J6 -> -0.22155689 | K5: =('Stock Prices'!L6-'Stock Prices'!K6)/'Stock Prices'!K6 -> 0.32307692 | L5: =('Stock Prices'!M6-'Stock Prices'!L6)/'Stock Prices'!L6 -> -0.27325581 | ... N5: =('Stock Prices'!O6-'Stock Prices'!N6)/'Stock Prices'!N6 -> 0.15591398
A6: AMP.MI | B6: Amplifon | C6: Italy | D6: FTSE MIB | E6: =('Stock Prices'!F7-'Stock Prices'!E7)/'Stock Prices'!E7 -> 0.63265306 | F6: =('Stock Prices'!G7-'Stock Prices'!F7)/'Stock Prices'!F7 -> 0.13125 | G6: =('Stock Prices'!H7-'Stock Prices'!G7)/'Stock Prices'!G7 -> 0.41878453 | H6: =('Stock Prices'!I7-'Stock Prices'!H7)/'Stock Prices'!H7 -> 0.09423676 | I6: =('Stock Prices'!J7-'Stock Prices'!I7)/'Stock Prices'!I7 -> 0.82491103 | J6: =('Stock Prices'!K7-'Stock Prices'!J7)/'Stock Prices'!J7 -> 0.3276131 | K6: =('Stock Prices'!L7-'Stock Prices'!K7)/'Stock Prices'!K7 -> 0.3939483 | L6: =('Stock Prices'!M7-'Stock Prices'!L7)/'Stock Prices'!L7 -> -0.41369863 | ... N6: =('Stock Prices'!O7-'Stock Prices'!N7)/'Stock Prices'!N7 -> -0.2070836
A7: G.MI | B7: Assicurazioni Generali | C7: Italy | D7: FTSE MIB | E7: =('Stock Prices'!F8-'Stock Prices'!E8)/'Stock Prices'!E8 -> -0.0047058824 | F7: =('Stock Prices'!G8-'Stock Prices'!F8)/'Stock Prices'!F8 -> -0.16548463 | G7: =('Stock Prices'!H8-'Stock Prices'!G8)/'Stock Prices'!G8 -> 0.076487252 | H7: =('Stock Prices'!I8-'Stock Prices'!H8)/'Stock Prices'!H8 -> -0.039473684 | I7: =('Stock Prices'!J8-'Stock Prices'!I8)/'Stock Prices'!I8 -> 0.26027397 | J7: =('Stock Prices'!K8-'Stock Prices'!J8)/'Stock Prices'!J8 -> -0.225 | K7: =('Stock Prices'!L8-'Stock Prices'!K8)/'Stock Prices'!K8 -> 0.30645161 | L7: =('Stock Prices'!M8-'Stock Prices'!L8)/'Stock Prices'!L8 -> -0.10842727 | ... N7: =('Stock Prices'!O8-'Stock Prices'!N8)/'Stock Prices'!N8 -> 0.42700157
A8: AZM.MI | B8: Azimut Holding | C8: Italy | D8: FTSE MIB | E8: =('Stock Prices'!F9-'Stock Prices'!E9)/'Stock Prices'!E9 -> 0.27915408 | F8: =('Stock Prices'!G9-'Stock Prices'!F9)/'Stock Prices'!F9 -> -0.31223429 | G8: =('Stock Prices'!H9-'Stock Prices'!G9)/'Stock Prices'!G9 -> 0.0068681319 | H8: =('Stock Prices'!I9-'Stock Prices'!H9)/'Stock Prices'!H9 -> -0.37039563 | I8: =('Stock Prices'!J9-'Stock Prices'!I9)/'Stock Prices'!I9 -> 1.2730228 | J8: =('Stock Prices'!K9-'Stock Prices'!J9)/'Stock Prices'!J9 -> -0.16491897 | K8: =('Stock Prices'!L9-'Stock Prices'!K9)/'Stock Prices'!K9 -> 0.38869863 | L8: =('Stock Prices'!M9-'Stock Prices'!L9)/'Stock Prices'!L9 -> -0.15207563 | ... N8: =('Stock Prices'!O9-'Stock Prices'!N9)/'Stock Prices'!N9 -> 0.029613734
A9: BGN.MI | B9: Banca Generali | C9: Italy | D9: FTSE MIB | E9: =('Stock Prices'!F10-'Stock Prices'!E10)/'Stock Prices'!E10 -> 0.2659436 | F9: =('Stock Prices'!G10-'Stock Prices'!F10)/'Stock Prices'!F10 -> -0.22344071 | G9: =('Stock Prices'!H10-'Stock Prices'!G10)/'Stock Prices'!G10 -> 0.22418358 | H9: =('Stock Prices'!I10-'Stock Prices'!H10)/'Stock Prices'!H10 -> -0.34643115 | I9: =('Stock Prices'!J10-'Stock Prices'!I10)/'Stock Prices'!I10 -> 0.59735245 | J9: =('Stock Prices'!K10-'Stock Prices'!J10)/'Stock Prices'!J10 -> -0.059392265 | K9: =('Stock Prices'!L10-'Stock Prices'!K10)/'Stock Prices'!K10 -> 0.42254038 | L9: =('Stock Prices'!M10-'Stock Prices'!L10)/'Stock Prices'!L10 -> -0.17264516 | ... N9: =('Stock Prices'!O10-'Stock Prices'!N10)/'Stock Prices'!N10 -> 0.33353151
A10: BMED.MI | B10: Banca Mediolanum | C10: Italy | D10: FTSE MIB | E10: =('Stock Prices'!F11-'Stock Prices'!E11)/'Stock Prices'!E11 -> 0.38185255 | F10: =('Stock Prices'!G11-'Stock Prices'!F11)/'Stock Prices'!F11 -> -0.065663475 | G10: =('Stock Prices'!H11-'Stock Prices'!G11)/'Stock Prices'!G11 -> 0.057101025 | H10: =('Stock Prices'!I11-'Stock Prices'!H11)/'Stock Prices'!H11 -> -0.29501385 | I10: =('Stock Prices'!J11-'Stock Prices'!I11)/'Stock Prices'!I11 -> 0.74066798 | J10: =('Stock Prices'!K11-'Stock Prices'!J11)/'Stock Prices'!J11 -> -0.1986456 | K10: =('Stock Prices'!L11-'Stock Prices'!K11)/'Stock Prices'!K11 -> 0.22253521 | L10: =('Stock Prices'!M11-'Stock Prices'!L11)/'Stock Prices'!L11 -> -0.10138249 | ... N10: =('Stock Prices'!O11-'Stock Prices'!N11)/'Stock Prices'!N11 -> 0.34701055
A11: BAMI.MI | B11: Banco BPM | C11: Italy | D11: FTSE MIB | E11: =('Stock Prices'!F12-'Stock Prices'!E12)/'Stock Prices'!E12 -> 0.27345845 | F11: =('Stock Prices'!G12-'Stock Prices'!F12)/'Stock Prices'!F12 -> -0.75894737 | G11: =('Stock Prices'!H12-'Stock Prices'!G12)/'Stock Prices'!G12 -> 0.1441048 | H11: =('Stock Prices'!I12-'Stock Prices'!H12)/'Stock Prices'!H12 -> -0.2480916 | I11: =('Stock Prices'!J12-'Stock Prices'!I12)/'Stock Prices'!I12 -> 0.030456853 | J11: =('Stock Prices'!K12-'Stock Prices'!J12)/'Stock Prices'!J12 -> -0.10837438 | K11: =('Stock Prices'!L12-'Stock Prices'!K12)/'Stock Prices'!K12 -> 0.45856354 | L11: =('Stock Prices'!M12-'Stock Prices'!L12)/'Stock Prices'!L12 -> 0.26136364 | ... N11: =('Stock Prices'!O12-'Stock Prices'!N12)/'Stock Prices'!N12 -> 0.63389121
A12: BPE.MI | B12: BPER Banca | C12: Italy | D12: FTSE MIB | E12: =('Stock Prices'!F13-'Stock Prices'!E13)/'Stock Prices'!E13 -> 0.28918919 | F12: =('Stock Prices'!G13-'Stock Prices'!F13)/'Stock Prices'!F13 -> -0.28092243 | G12: =('Stock Prices'!H13-'Stock Prices'!G13)/'Stock Prices'!G13 -> -0.16909621 | H12: =('Stock Prices'!I13-'Stock Prices'!H13)/'Stock Prices'!H13 -> -0.2 | I12: =('Stock Prices'!J13-'Stock Prices'!I13)/'Stock Prices'!I13 -> 0.32894737 | J12: =('Stock Prices'!K13-'Stock Prices'!J13)/'Stock Prices'!J13 -> -0.50825083 | K12: =('Stock Prices'!L13-'Stock Prices'!K13)/'Stock Prices'!K13 -> 0.22147651 | L12: =('Stock Prices'!M13-'Stock Prices'!L13)/'Stock Prices'!L13 -> 0.054945055 | ... N12: =('Stock Prices'!O13-'Stock Prices'!N13)/'Stock Prices'!N13 -> 1.0231023
